Workbook

Sheet Árbol de navegación
A1: Árbol de navegación por grupo, categoría y grupo de interés
A2: Nivel 1 = grupo de audiencia · Nivel 2 = categoría · Nivel 3 = grupo de la categoría. Los conteos se calculan desde cada hoja.
A4: Nivel 1 | B4: Nivel 2 · Categoría | C4: Nivel 3 · Grupo | D4: Páginas
A5: Contribuyentes | D5: =COUNTA(Contribuyentes!$G$5:$G$357)
B6: NIT sin Obligaciones | D6: =COUNTIF(Contribuyentes!$A$5:$A$357,B6)
C7: Todos los grupos | D7: =COUNTIFS(Contribuyentes!$A$5:$A$357,$B$6,Contribuyentes!$B$5:$B$357,C7)
B8: Pequeños Contribuyentes | D8: =COUNTIF(Contribuyentes!$A$5:$A$357,B8)
C9: Todos los grupos | D9: =COUNTIFS(Contribuyentes!$A$5:$A$357,$B$8,Contribuyentes!$B$5:$B$357,C9)
C10: Pequeño Contribuyente | D10: =COUNTIFS(Contribuyentes!$A$5:$A$357,$B$8,Contribuyentes!$B$5:$B$357,C10)
C11: Primario | D11: =COUNTIFS(Contribuyentes!$A$5:$A$357,$B$8,Contribuyentes!$B$5:$B$357,C11)
C12: Pecuario | D12: =COUNTIFS(Contribuyentes!$A$5:$A$357,$B$8,Contribuyentes!$B$5:$B$357,C12)
B13: Contribuyente General | D13: =COUNTIF(Contribuyentes!$A$5:$A$357,B13)
C14: Todos los grupos | D14: =COUNTIFS(Contribuyentes!$A$5:$A$357,$B$13,Contribuyentes!$B$5:$B$357,C14)
C15: Contribuyente General | D15: =COUNTIFS(Contribuyentes!$A$5:$A$357,$B$13,Contribuyentes!$B$5:$B$357,C15)
C16: Rep. Legales | D16: =COUNTIFS(Contribuyentes!$A$5:$A$357,$B$13,Contribuyentes!$B$5:$B$357,C16)
B17: Contribuyentes Especiales | D17: =COUNTIF(Contribuyentes!$A$5:$A$357,B17)
C18: Todos los grupos | D18: =COUNTIFS(Contribuyentes!$A$5:$A$357,$B$17,Contribuyentes!$B$5:$B$357,C18)
C19: Medianos | D19: =COUNTIFS(Contribuyentes!$A$5:$A$357,$B$17,Contribuyentes!$B$5:$B$357,C19)
C20: Grandes | D20: =COUNTIFS(Contribuyentes!$A$5:$A$357,$B$17,Contribuyentes!$B$5:$B$357,C20)
C21: Rep. Legales | D21: =COUNTIFS(Contribuyentes!$A$5:$A$357,$B$17,Contribuyentes!$B$5:$B$357,C21)
B22: Trámites comunes | D22: =COUNTIF(Contribuyentes!$A$5:$A$357,B22)
C23: Todos los grupos | D23: =COUNTIFS(Contribuyentes!$A$5:$A$357,$B$22,Contribuyentes!$B$5:$B$357,C23)
A24: Operadores de comercio exterior | D24: =COUNTA('Operadores de comercio exterior'!$F$5:$F$174)
B25: Importadores y Exportadores | D25: =COUNTIF('Operadores de comercio exterior'!$A$5:$A$174,B25)
C26: Todos los grupos | D26: =COUNTIFS('Operadores de comercio exterior'!$A$5:$A$174,$B$25,'Operadores de comercio exterior'!$B$5:$B$174,C26)
C27: Importadores | D27: =COUNTIFS('Operadores de comercio exterior'!$A$5:$A$174,$B$25,'Operadores de comercio exterior'!$B$5:$B$174,C27)
C28: OEA | D28: =COUNTIFS('Operadores de comercio exterior'!$A$5:$A$174,$B$25,'Operadores de comercio exterior'!$B$5:$B$174,C28)
C29: Exportadores | D29: =COUNTIFS('Operadores de comercio exterior'!$A$5:$A$174,$B$25,'Operadores de comercio exterior'!$B$5:$B$174,C29)
B30: Auxiliares de la Función Pública Aduanera | D30: =COUNTIF('Operadores de comercio exterior'!$A$5:$A$174,B30)
C31: Todos los grupos | D31: =COUNTIFS('Operadores de comercio exterior'!$A$5:$A$174,$B$30,'Operadores de comercio exterior'!$B$5:$B$174,C31)
C32: Courier | D32: =COUNTIFS('Operadores de comercio exterior'!$A$5:$A$174,$B$30,'Operadores de comercio exterior'!$B$5:$B$174,C32)
C33: Consolidadores y Desconsolidadores de Carga | D33: =COUNTIFS('Operadores de comercio exterior'!$A$5:$A$174,$B$30,'Operadores de comercio exterior'!$B$5:$B$174,C33)
C34: Almacenes Fiscales | D34: =COUNTIFS('Operadores de comercio exterior'!$A$5:$A$174,$B$30,'Operadores de comercio exterior'!$B$5:$B$174,C34)
C35: Almacenadoras | D35: =COUNTIFS('Operadores de comercio exterior'!$A$5:$A$174,$B$30,'Operadores de comercio exterior'!$B$5:$B$174,C35)
C36: Depósitos Aduaneros | D36: =COUNTIFS('Operadores de comercio exterior'!$A$5:$A$174,$B$30,'Operadores de comercio exterior'!$B$5:$B$174,C36)
C37: ZDEEP | D37: =COUNTIFS('Operadores de comercio exterior'!$A$5:$A$174,$B$30,'Operadores de comercio exterior'!$B$5:$B$174,C37)
C38: Agentes Aduaneros | D38: =COUNTIFS('Operadores de comercio exterior'!$A$5:$A$174,$B$30,'Operadores de comercio exterior'!$B$5:$B$174,C38)
C39: Transportistas | D39: =COUNTIFS('Operadores de comercio exterior'!$A$5:$A$174,$B$30,'Operadores de comercio exterior'!$B$5:$B$174,C39)
C40: Apoderado Especial Aduanero | D40: =COUNTIFS('Operadores de comercio exterior'!$A$5:$A$174,$B$30,'Operadores de comercio exterior'!$B$5:$B$174,C40)
B41: Trámites comunes | D41: =COUNTIF('Operadores de comercio exterior'!$A$5:$A$174,B41)
...

Sheet Descripciones
A1: Descripciones de categorías y grupos
A2: Para qué sirve cada nivel desde el portal SAT y la base legal de referencia (verificar contra la versión vigente de cada ley).
A4: Nivel 1 | B4: Categoría | C4: Grupo | D4: Para quién es | E4: Base legal de referencia | F4: Páginas
A5: Contribuyentes | D5: Personas y empresas inscritas en el RTU: inscripción, declaraciones, facturas, vehículos, devoluciones y más. | E5: Código Tributario (Decreto 6-91): Registro Tributario Unificado. | F5: =COUNTA(Contribuyentes!$G$5:$G$357)
A6: Contribuyentes | B6: NIT sin Obligaciones | D6: Personas con NIT que no están afiliadas a impuestos: asalariados, personas que compran bienes o hacen trámites de vehículos y profesionales que registran su título. | E6: Código Tributario (RTU); Ley de Actualización Tributaria (Decreto 10-2012), ISR de rentas del trabajo. | F6: =COUNTIF(Contribuyentes!$A$5:$A$357,B6)
A7: Contribuyentes | B7: Pequeños Contribuyentes | D7: Contribuyentes de regímenes simplificados: pequeño contribuyente y los nuevos regímenes del sector primario y pecuario. | E7: Ley del IVA (Decreto 27-92), Régimen de Pequeño Contribuyente; Decreto 31-2024. | F7: =COUNTIF(Contribuyentes!$A$5:$A$357,B7)
A8: Contribuyentes | B8: Pequeños Contribuyentes | C8: Pequeño Contribuyente | D8: Personas con ingresos anuales de hasta Q150,000 que pagan una tarifa única sobre sus ventas (incluye el Régimen Electrónico). | E8: Ley del IVA (Decreto 27-92), Régimen de Pequeño Contribuyente; Decreto 7-2019 (régimen electrónico). | F8: =COUNTIFS(Contribuyentes!$A$5:$A$357,B8,Contribuyentes!$B$5:$B$357,C8)
A9: Contribuyentes | B9: Pequeños Contribuyentes | C9: Primario | D9: Productores agrícolas y artesanales del sector primario inscritos en el régimen especial, con pago del Impuesto a la Confianza Tributaria (ICT). | E9: Ley para la Integración del Sector Productivo Primario y Agropecuario (Decreto 31-2024). | F9: =COUNTIFS(Contribuyentes!$A$5:$A$357,B9,Contribuyentes!$B$5:$B$357,C9)
A10: Contribuyentes | B10: Pequeños Contribuyentes | C10: Pecuario | D10: Productores e intermediarios de ganado, acuicultura y apicultura sin transformación industrial, inscritos en el régimen pecuario (ICT). | E10: Decreto 31-2024, régimen pecuario. | F10: =COUNTIFS(Contribuyentes!$A$5:$A$357,B10,Contribuyentes!$B$5:$B$357,C10)
A11: Contribuyentes | B11: Contribuyente General | D11: Contribuyentes del Régimen General del IVA y del ISR de actividades lucrativas (sobre utilidades u opcional simplificado), incluidas personas jurídicas y entes. | E11: Ley del IVA (Decreto 27-92); Ley de Actualización Tributaria (Decreto 10-2012). | F11: =COUNTIF(Contribuyentes!$A$5:$A$357,B11)
A12: Contribuyentes | B12: Contribuyente General | C12: Contribuyente General | D12: Personas individuales y jurídicas con negocio en el Régimen General. | E12: Decreto 27-92 y Decreto 10-2012. | F12: =COUNTIFS(Contribuyentes!$A$5:$A$357,B12,Contribuyentes!$B$5:$B$357,C12)
A13: Contribuyentes | B13: Contribuyente General | C13: Rep. Legales | D13: Representantes legales que hacen gestiones en nombre de personas jurídicas. | E13: Código Tributario, responsables por representación; Código de Comercio. | F13: =COUNTIFS(Contribuyentes!$A$5:$A$357,B13,Contribuyentes!$B$5:$B$357,C13)
A14: Contribuyentes | B14: Contribuyentes Especiales | D14: Contribuyentes calificados por la SAT como especiales por su volumen de operaciones; atención en gerencias especializadas. | E14: Calificación por resolución de la SAT (Ley Orgánica de la SAT, Decreto 1-98). | F14: =COUNTIF(Contribuyentes!$A$5:$A$357,B14)
A15: Contribuyentes | B15: Contribuyentes Especiales | C15: Medianos | D15: Contribuyentes especiales medianos. | E15: Resolución de calificación de la SAT. | F15: =COUNTIFS(Contribuyentes!$A$5:$A$357,B15,Contribuyentes!$B$5:$B$357,C15)
A16: Contribuyentes | B16: Contribuyentes Especiales | C16: Grandes | D16: Contribuyentes especiales grandes. | E16: Resolución de calificación de la SAT. | F16: =COUNTIFS(Contribuyentes!$A$5:$A$357,B16,Contribuyentes!$B$5:$B$357,C16)
A17: Contribuyentes | B17: Contribuyentes Especiales | C17: Rep. Legales | D17: Representantes legales de contribuyentes especiales. | E17: Código Tributario, responsables por representación. | F17: =COUNTIFS(Contribuyentes!$A$5:$A$357,B17,Contribuyentes!$B$5:$B$357,C17)
A18: Operadores de comercio exterior | D18: Personas que importan, exportan o prestan servicios en las operaciones aduaneras. | E18: CAUCA y RECAUCA; Ley Nacional de Aduanas (Decreto 14-2013). | F18: =COUNTA('Operadores de comercio exterior'!$F$5:$F$174)
A19: Operadores de comercio exterior | B19: Importadores y Exportadores | D19: Personas y empresas que importan o exportan mercancías. | E19: CAUCA y RECAUCA; Ley del IVA (devolución de crédito fiscal). | F19: =COUNTIF('Operadores de comercio exterior'!$A$5:$A$174,B19)
A20: Operadores de comercio exterior | B20: Importadores y Exportadores | C20: Importadores | D20: Quienes ingresan mercancías o vehículos al país. | E20: CAUCA y RECAUCA. | F20: =COUNTIFS('Operadores de comercio exterior'!$A$5:$A$174,B20,'Operadores de comercio exterior'!$B$5:$B$174,C20)
A21: Operadores de comercio exterior | B21: Importadores y Exportadores | C21: OEA | D21: Operadores Económicos Autorizados: empresas certificadas por cumplir estándares de seguridad y bajo riesgo. | E21: CAUCA y RECAUCA; programa OEA de la SAT. | F21: =COUNTIFS('Operadores de comercio exterior'!$A$5:$A$174,B21,'Operadores de comercio exterior'!$B$5:$B$174,C21)
A22: Operadores de comercio exterior | B22: Importadores y Exportadores | C22: Exportadores | D22: Quienes venden mercancías al exterior: registro de exportadores y devolución del crédito fiscal del IVA. | E22: Ley del IVA (Decreto 27-92), regímenes de devolución de crédito fiscal. | F22: =COUNTIFS('Operadores de comercio exterior'!$A$5:$A$174,B22,'Operadores de comercio exterior'!$B$5:$B$174,C22)
A23: Operadores de comercio exterior | B23: Auxiliares de la Función Pública Aduanera | D23: Personas autorizadas por la SAT que intervienen en las operaciones aduaneras. | E23: CAUCA y RECAUCA, auxiliares de la función pública aduanera; Decreto 14-2013. | F23: =COUNTIF('Operadores de comercio exterior'!$A$5:$A$174,B23)
A24: Operadores de comercio exterior | B24: Auxiliares de la Función Pública Aduanera | C24: Courier | D24: Empresas de entrega rápida. | E24: RECAUCA. | F24: =COUNTIFS('Operadores de comercio exterior'!$A$5:$A$174,B24,'Operadores de comercio exterior'!$B$5:$B$174,C24)
A25: Operadores de comercio exterior | B25: Auxiliares de la Función Pública Aduanera | C25: Consolidadores y Desconsolidadores de Carga | D25: Agrupan o separan carga de varios consignatarios. | E25: RECAUCA. | F25: =COUNTIFS('Operadores de comercio exterior'!$A$5:$A$174,B25,'Operadores de comercio exterior'!$B$5:$B$174,C25)
A26: Operadores de comercio exterior | B26: Auxiliares de la Función Pública Aduanera | C26: Almacenes Fiscales | D26: Depositarios aduaneros que almacenan mercancías bajo control aduanero. | E26: RECAUCA. | F26: =COUNTIFS('Operadores de comercio exterior'!$A$5:$A$174,B26,'Operadores de comercio exterior'!$B$5:$B$174,C26)
A27: Operadores de comercio exterior | B27: Auxiliares de la Función Pública Aduanera | C27: Almacenadoras | D27: Almacenes generales de depósito autorizados. | E27: RECAUCA. | F27: =COUNTIFS('Operadores de comercio exterior'!$A$5:$A$174,B27,'Operadores de comercio exterior'!$B$5:$B$174,C27)
A28: Operadores de comercio exterior | B28: Auxiliares de la Función Pública Aduanera | C28: Depósitos Aduaneros | D28: Depósitos autorizados para mercancías en régimen suspensivo. | E28: RECAUCA. | F28: =COUNTIFS('Operadores de comercio exterior'!$A$5:$A$174,B28,'Operadores de comercio exterior'!$B$5:$B$174,C28)
A29: Operadores de comercio exterior | B29: Auxiliares de la Función Pública Aduanera | C29: ZDEEP | D29: Desarrolladores de Zonas de Desarrollo Económico Especial Públicas, registrados como auxiliares. | E29: Decreto 22-73 (ZOLIC), reformado por Decreto 30-2008. | F29: =COUNTIFS('Operadores de comercio exterior'!$A$5:$A$174,B29,'Operadores de comercio exterior'!$B$5:$B$174,C29)
A30: Operadores de comercio exterior | B30: Auxiliares de la Función Pública Aduanera | C30: Agentes Aduaneros | D30: Profesionales autorizados para presentar declaraciones de mercancías por cuenta de terceros. | E30: CAUCA y RECAUCA. | F30: =COUNTIFS('Operadores de comercio exterior'!$A$5:$A$174,B30,'Operadores de comercio exterior'!$B$5:$B$174,C30)
A31: Operadores de comercio exterior | B31: Auxiliares de la Función Pública Aduanera | C31: Transportistas | D31: Transportistas aduaneros: manifiestos, marchamo y tránsito. | E31: CAUCA y RECAUCA. | F31: =COUNTIFS('Operadores de comercio exterior'!$A$5:$A$174,B31,'Operadores de comercio exterior'!$B$5:$B$174,C31)
A32: Operadores de comercio exterior | B32: Auxiliares de la Función Pública Aduanera | C32: Apoderado Especial Aduanero | D32: Representante del importador o exportador en sus propias operaciones. | E32: Ley Nacional de Aduanas (Decreto 14-2013). | F32: =COUNTIFS('Operadores de comercio exterior'!$A$5:$A$174,B32,'Operadores de comercio exterior'!$B$5:$B$174,C32)
A33: Profesionales | D33: Personas que hacen gestiones ante la SAT por cuenta de otros. | F33: =COUNTA(Profesionales!$F$5:$F$94)
A34: Profesionales | B34: Terceras Personas | D34: Terceras personas autorizadas o registradas ante la SAT. | F34: =COUNTIF(Profesionales!$A$5:$A$94,B34)
A35: Profesionales | B35: Terceras Personas | C35: Gestores Tributarios | D35: Personas autorizadas por la SAT para hacer gestiones de terceros, principalmente de vehículos. | E35: Registro y autorización de la SAT. | F35: =COUNTIFS(Profesionales!$A$5:$A$94,B35,Profesionales!$B$5:$B$94,C35)
A36: Profesionales | B36: Terceras Personas | C36: Auxiliar Tributario | D36: Auxiliares de los gestores tributarios. | E36: Registro y autorización de la SAT. | F36: =COUNTIFS(Profesionales!$A$5:$A$94,B36,Profesionales!$B$5:$B$94,C36)
A37: Profesionales | B37: Terceras Personas | C37: Abogados y Notarios | D37: Registro de abogados y notarios, avisos notariales, traspasos electrónicos y especies fiscales. | E37: Código de Notariado (Decreto 314); Ley del Impuesto de Timbres Fiscales (Decreto 37-92). | F37: =COUNTIFS(Profesionales!$A$5:$A$94,B37,Profesionales!$B$5:$B$94,C37)
A38: Profesionales | B38: Terceras Personas | C38: Peritos Contadores | D38: Contadores inscritos que llevan la contabilidad de los contribuyentes. | E38: Decreto 10-2012 (contabilidad); Código de Comercio. | F38: =COUNTIFS(Profesionales!$A$5:$A$94,B38,Profesionales!$B$5:$B$94,C38)
A39: Profesionales | B39: Terceras Personas | C39: Auditores | D39: Contadores públicos y auditores que emiten dictámenes ante la SAT. | E39: Decreto 10-2012; Ley del IVA (dictamen para devolución de crédito fiscal). | F39: =COUNTIFS(Profesionales!$A$5:$A$94,B39,Profesionales!$B$5:$B$94,C39)
A40: Organismos especiales | D40: Entidades con régimen especial de exención y entidades del Estado. | F40: =COUNTA('Organismos especiales'!$F$5:$F$137)
A41: Organismos especiales | B41: Exentos | D41: Entidades exentas de impuestos según la Constitución o leyes específicas. | E41: Constitución Política; Decreto 10-2012, art. 11 (rentas exentas). | F41: =COUNTIF('Organismos especiales'!$A$5:$A$137,B41)
...

Sheet Contribuyentes
A1: Contribuyentes
A2: Personas individuales y jurídicas inscritas en el RTU, ordenadas por categoría (régimen o tipo de contribuyente) y grupo. Orden: Categoría › Grupo › Tema › Página. «Todos los grupos» = la usan todos los grupos de la categoría. «Trámites comunes» = la usan varias categorías.
A4: Macro Grupos | B4: Grupo | C4: Sub grupo | D4: Tema | E4: Subtema | F4: Página / Trámite (nombre actual) | G4: Nombre de trámite sugerido | H4: Descripción de la página | I4: Usado por (según Grupos y categorías) | J4: Origen de la clasificación | K4: Motivo / referencia | L4: Sección actual del menú | M4: URL | N4: Nota / Revisar
A5: Contribuyente General | B5: Todos los grupos | D5: Devoluciones y créditos fiscales | E5: ISR (Impuesto Sobre la Renta) | F5: Devolución de ISR Asalariados (Retenciones en exceso o pago indebido) SAT-117 o 1431 | G5: Devolución de ISR si eres asalariado | H5: Información sobre: Devolución de ISR si eres asalariado. | J5: Análisis | K5: Asalariados: NIT sin obligaciones, ISR de rentas del trabajo | L5: SERVICIOS TRIBUTARIOS | M5: https://portal.sat.gob.gt/portal/requisitos-tramites-agencias/devolucion-del-impuesto-sobre-la-renta-asalariados-retenciones-en-exceso-o-pago-indebido/ | N5: Servicio/tema general para contribuyentes
A6: Contribuyentes | B6: NIT sin Obligaciones | D6: RTU Digital | E6: Inscripción | F6: Requisitos para la Inscripción RTU | G6: Inscripción de NIT sin Obligaciones | H6: Solicitud y requisitos para la obtención electrónica de NIT sin obligaciones tributarias por primera vez. | I6: Personas Individuales (Nacionales y Extranjeros sin actividad económica) | J6: Análisis de arquitectura transaccional | K6: Trámite inicial obligatorio para actos civiles, apertura de cuentas bancarias y recepción de remesas. | L6: Requisitos de personas / empresas | M6: https://portal.sat.gob.gt/portal/requisitos-de-personas-empresas/#1615485066841-639e67c5-51e3 | N6: Desvincular del listado de empresas/sociedades mercantiles; crear landing o ficha específica para personas individuales.
A7: Contribuyentes | B7: NIT sin Obligaciones | D7: RTU Digital | E7: Actualización | F7: Requisitos para la Actualización RTU | G7: Actualización de Datos y Transición de Régimen | H7: Requisitos y pasos para actualizar datos de identificación, domicilio fiscal o pasar al régimen con obligaciones tributarias. | I7: Personas que inician relación laboral o comercial | J7: Análisis de arquitectura transaccional | K7: Permite modificar datos personales o dar el salto formal a contribuyente afecto cuando la persona inicia actividades económicas. | L7: Requisitos de personas / empresas | M7: https://portal.sat.gob.gt/portal/requisitos-de-personas-empresas/#1541621044169-4198d06d-693f | N7: Aislar la opción de paso de 'sin obligaciones' a 'con obligaciones' sin obligar a navegar por requisitos corporativos.
A8: Contribuyentes | B8: NIT sin Obligaciones | D8: Sistemas Web | E8: Acceso y Seguridad | F8: Agencia Virtual | G8: Solicitud y Activación de Agencia Virtual | H8: Acceso a plataforma, activación de usuario, reinicio de contraseña y cambio de correo electrónico para personas sin obligaciones. | I8: Usuarios registrados con NIT | J8: Análisis de arquitectura transaccional | K8: Canal indispensable para descargar la constancia de RTU, consultar datos personales y dar seguimiento a solicitudes web. | L8: Menú Principal / Sistemas | M8: https://farm3.sat.gob.gt/menu/login.jsf | N8: Es un sistema de autenticación directa; la ficha informativa debe explicar cómo obtener el acceso inicial.
A9: Contribuyentes | B9: NIT sin Obligaciones | D9: Consultas Públicas | E9: Seguimiento | F9: Estado de Gestión de Agencia Virtual | G9: Consulta de Estado de Gestión de Agencia Virtual | H9: Herramienta de consulta para verificar el estado de aprobación de la solicitud de acceso a Agencia Virtual. | I9: Solicitantes de Agencia Virtual | J9: Análisis de arquitectura transaccional | K9: Permite validar si la solicitud de usuario o reseteo de clave fue aceptada, rechazada o requiere subsanar requisitos. | L9: Consultas Públicas | M9: https://portal.sat.gob.gt/portal/consulta-de-gestion-del-contribuyente/ | N9: Debe integrarse como paso de seguimiento dentro de la ficha de Agencia Virtual, no como enlace huérfano.
A10: Contribuyentes | B10: NIT sin Obligaciones | D10: Certificaciones | E10: Solvencias | F10: Solvencia Fiscal | G10: Solicitud y Emisión de Solvencia Fiscal (SOFI) | H10: Consulta, pago y descarga de la Solvencia Fiscal Electrónica para certificar ausencia de adeudos tributarios. | I10: Personas Individuales | J10: Análisis de arquitectura transaccional | K10: Exigida comúnmente a personas sin obligaciones para postulaciones laborales, trámites consulares/visas y contratos civiles. | L10: Consultas / Solvencias | M10: https://portal.sat.gob.gt/portal/solvencia-fiscal/ | N10: Para este perfil la emisión es automática, salvo que existan registros históricos de omisos o adeudos en el ISCV.
A11: Contribuyentes | B11: NIT sin Obligaciones | D11: Citas y Agencias | E11: Citas | F11: Requisitos para la Atención a través de Cita | G11: Cita Previa para Trámites Presenciales | H11: Información, requisitos y agenda electrónica para programar atención física en agencias tributarias. | I11: Casos especiales (menores o extranjeros) | J11: Análisis de arquitectura transaccional | K11: Aplica a personas sin obligaciones únicamente en validaciones biométricas presenciales o trámites mediante representante legal. | L11: Requisitos trámites agencias | M11: https://portal.sat.gob.gt/portal/requisitos-tramites-agencias/cita-controlada/ | N11: Condicional: solo debe desplegarse como alternativa si el trámite inicial no logra completarse 100% en línea.
A12: NIT sin Obligaciones | B12: Todos los grupos | D12: Otros servicios al contribuyente | E12: Títulos universitarios | F12: Títulos Universitarios | G12: Información sobre títulos universitarios | H12: Información sobre: Información sobre títulos universitarios. | J12: Análisis | K12: Profesionales que registran su título (NIT sin obligaciones) | L12: SERVICIOS TRIBUTARIOS | M12: https://portal.sat.gob.gt/portal/titulos-universitarios/ | N12: Servicio/tema general para contribuyentes
A13: NIT sin Obligaciones | B13: Todos los grupos | D13: Otros servicios al contribuyente | E13: Títulos universitarios | F13: Registro y Habilitación de Títulos Universitarios | G13: Registrar tu título universitario para ejercer | H13: Requisitos, pasos y documentos para registrar tu título universitario para ejercer. | I13: NIT sin Obligaciones | J13: Grupos y categorías | K13: Marcada «SI» en el archivo Grupos y categorías | L13: SERVICIOS TRIBUTARIOS | M13: https://portal.sat.gob.gt/portal/requisitos-tramites-agencias/registro-y-habilitacion-de-titulos-para-ejercer-profesion/ | N13: Servicio/tema general para contribuyentes
A14: NIT sin Obligaciones | B14: Todos los grupos | D14: Vehículos (como propietario) | E14: Requisitos y representantes | F14: Temas De Vehiculos | G14: Preguntas frecuentes sobre vehículos | H14: Respuestas a las preguntas más comunes sobre requisitos y representantes. | I14: NIT sin Obligaciones | J14: Grupos y categorías | K14: Marcada «SI» en el archivo Grupos y categorías | L14: CAPACITACIÓN | M14: https://portal.sat.gob.gt/portal/preguntas-frecuentes/temas-de-vehiculos/ | N14: Servicio/tema general para contribuyentes
A15: NIT sin Obligaciones | B15: Todos los grupos | D15: Vehículos (como propietario) | E15: Título y tarjeta de circulación | F15: Distintivos Electrónicos (Título de propiedad y Tarjeta de Circulación) | G15: Título y tarjeta de circulación electrónicos | H15: Información sobre: Título y tarjeta de circulación electrónicos. | I15: NIT sin Obligaciones | J15: Grupos y categorías | K15: Marcada «SI» en el archivo Grupos y categorías | L15: SERVICIOS TRIBUTARIOS | M15: https://portal.sat.gob.gt/portal/distintivos-electronicos/ | N15: Servicio/tema general para contribuyentes
A16: NIT sin Obligaciones | B16: Todos los grupos | D16: Agregada desde «Grupos y categorías» | G16: Libro Electrónico Tributario | H16: Pequeño Contribuyente | I16: NIT sin Obligaciones | J16: Grupos y categorías | K16: Marcada «SI» en el archivo Grupos y categorías | M16: https://portal.sat.gob.gt/portal/libro-electronico-tributario/pequeno-contribuyente/
A17: Pequeños Contribuyentes | B17: Todos los grupos | D17: Cultura tributaria y capacitación | E17: Leyes y normativa | F17: Legislación | G17: Legislación | H17: Información sobre: Legislación. | I17: Pequeños Contribuyentes | J17: Grupos y categorías | K17: Marcada «SI» en el archivo Grupos y categorías | L17: CAPACITACIÓN | M17: https://portal.sat.gob.gt/portal/biblioteca-en-linea-sat/legislacion/ | N17: Servicio/tema general para contribuyentes
A18: Pequeños Contribuyentes | B18: Todos los grupos | D18: Facturación electrónica y documentos tributarios | E18: Constancias de retención | F18: Constancias de Retención del IVA e ISR recibidos | G18: Consultar constancias de retención de IVA e ISR recibidas | H18: Servicio en línea para consultar constancias de retención de IVA e ISR recibidas. | I18: Pequeños Contribuyentes | J18: Grupos y categorías | K18: Marcada «SI» en el archivo Grupos y categorías | L18: SERVICIOS TRIBUTARIOS | M18: https://portal.sat.gob.gt/portal/retenciones-del-iva-consulta-de-constancias-de-retencion-del-iva-recibidas/ | N18: Servicio/tema general para contribuyentes
A19: Pequeños Contribuyentes | B19: Todos los grupos | D19: Importación | E19: Proceso de importación | F19: Despacho de distintivos de control de productos importados a los fabricantes o importadores domiciliados en el país y a las personas individuales y jurídicas que no sean fabricantes ni importadores | G19: Obtener distintivos de control de productos importados | H19: Requisitos, pasos y documentos para obtener distintivos de control de productos importados. | I19: Pequeños Contribuyentes | J19: Grupos y categorías | K19: Marcada «SI» en el archivo Grupos y categorías | L19: SERVICIOS TRIBUTARIOS | M19: https://portal.sat.gob.gt/portal/requisitos-tramites-agencias/despacho-de-distintivos-de-control-de-productos-importados-a-los-fabricantes-o-importadores-domiciliados-en-el-pais-y-a-las-personas-individuales-y-juridicas/ | N19: Coincide con palabra clave de comercio exterior/aduanas
A20: Pequeños Contribuyentes | B20: Todos los grupos | D20: Inscripción y actualización en el RTU | E20: Obtener o corregir tu NIT | F20: Solicitud Electrónica de NIT | G20: Solicitar tu NIT en línea | H20: Requisitos, pasos y documentos para solicitar tu NIT en línea. | I20: Pequeños Contribuyentes | J20: Grupos y categorías | K20: Marcada «SI» en el archivo Grupos y categorías | L20: SERVICIOS TRIBUTARIOS | M20: https://portal.sat.gob.gt/portal/solicitud-electronica-de-nit/ | N20: Servicio/tema general para contribuyentes
A21: Pequeños Contribuyentes | B21: Todos los grupos | D21: Otros servicios al contribuyente | E21: Sistemas de retención | F21: Asiste Hospitales Web | G21: Retenciones de hospitales (Asiste Hospitales Web) | H21: Información sobre: Retenciones de hospitales (Asiste Hospitales Web). | I21: Pequeños Contribuyentes | J21: Grupos y categorías | K21: Marcada «SI» en el archivo Grupos y categorías | L21: SERVICIOS TRIBUTARIOS | M21: https://portal.sat.gob.gt/portal/sistemas-web/asistehospitalesweb/ | N21: Servicio/tema general para contribuyentes
A22: Pequeños Contribuyentes | B22: Pequeño Contribuyente | D22: Cultura tributaria y capacitación | E22: Cursos por tipo de contribuyente | F22: Principales obligaciones tributarias de los pequeños contribuyentes | G22: Curso: obligaciones del pequeño contribuyente | H22: Capacitación virtual de la SAT sobre obligaciones del pequeño contribuyente. | J22: Análisis | K22: Régimen de Pequeño Contribuyente (Ley del IVA) | L22: CAPACITACIÓN | M22: https://sites.google.com/capacitacionessat.page/cultura-tributariad/cursos-virtuales-sat/impuesto-al-valor-agregado-iva/r%C3%A9gimen-del-peque%C3%B1o-contribuyente | N22: Servicio/tema general para contribuyentes
A23: Pequeños Contribuyentes | B23: Pequeño Contribuyente | D23: Devoluciones y créditos fiscales | E23: ISR (Impuesto Sobre la Renta) | F23: Devolución o Compensación del Impuesto Sobre la Renta Retenido al Pequeño Contribuyente del 5% | G23: Devolución del 5% de ISR retenido al pequeño contribuyente | H23: Información sobre: Devolución del 5% de ISR retenido al pequeño contribuyente. | J23: Análisis | K23: Retención de ISR al pequeño contribuyente | L23: SERVICIOS TRIBUTARIOS | M23: https://portal.sat.gob.gt/portal/requisitos-tramites-agencias/devolucion-acreditamiento-o-compensacion-de-impuesto-sobre-la-renta-retenido-indebidamente-a-pequeno-contribuyente-del-5/ | N23: Servicio/tema general para contribuyentes
A24: Pequeños Contribuyentes | B24: Pequeño Contribuyente | D24: Facturación electrónica y documentos tributarios | E24: Libro Electrónico Tributario (LET) | F24: Libro Electrónico Tributario para Pequeño contribuyente | G24: Curso: LET para pequeño contribuyente | H24: Capacitación virtual de la SAT sobre LET para pequeño contribuyente. | J24: Análisis | K24: Libro Electrónico Tributario del pequeño contribuyente | L24: CAPACITACIÓN | M24: https://sites.google.com/capacitacionessat.page/eventosenvivo/p%C3%A1gina-principal/libro-electr%C3%B3nico-tributario-para-peque%C3%B1o-contribuyente | N24: Servicio/tema general para contribuyentes
A25: Pequeños Contribuyentes | B25: Pequeño Contribuyente | D25: Otros servicios al contribuyente | E25: Libros, facturas y máquinas | F25: Autorización de documentos tributarios a pequeños contribuyentes | G25: Autorizar documentos para pequeños contribuyentes | H25: Requisitos, pasos y documentos para autorizar documentos para pequeños contribuyentes. | J25: Análisis | K25: Documentos del pequeño contribuyente | L25: SERVICIOS TRIBUTARIOS | M25: https://portal.sat.gob.gt/portal/requisitos-tramites-agencias/autorizacion-de-documentos-tributarios-a-pequenos-contribuyentes/ | N25: Servicio/tema general para contribuyentes
A26: Pequeños Contribuyentes | B26: Pequeño Contribuyente | D26: Regímenes tributarios | E26: Cambio de régimen | F26: Actualización de Cambio de Régimen de Pequeño Contribuyente a Régimen Electrónico de Pequeño Contribuyente | G26: Pasar a Régimen Electrónico de Pequeño Contribuyente | H26: Requisitos, pasos y documentos para pasar a Régimen Electrónico de Pequeño Contribuyente. | J26: Análisis | K26: Régimen de Pequeño Contribuyente (Ley del IVA) | L26: SERVICIOS TRIBUTARIOS | M26: https://portal.sat.gob.gt/portal/requisitos-tramites-agencias/requisitos-de-actualizacion-de-cambio-de-regimen-general-a-pequeno-contribuyente-persona/ | N26: Servicio/tema general para contribuyentes
A27: Pequeños Contribuyentes | B27: Pequeño Contribuyente | D27: Regímenes tributarios | E27: Cambio de régimen | F27: Actualización Cambio de Régimen de Pequeño Contribuyente a Régimen General del Impuesto al Valor Agregado | G27: Pasar de Pequeño Contribuyente a Régimen General del IVA | H27: Requisitos, pasos y documentos para pasar de Pequeño Contribuyente a Régimen General del IVA. | J27: Análisis | K27: Régimen de Pequeño Contribuyente (Ley del IVA) | L27: SERVICIOS TRIBUTARIOS | M27: https://portal.sat.gob.gt/portal/requisitos-tramites-agencias/actualizacion-cambio-de-regimen-de-pequeno-contribuyente-a-regimen-general-del-impuesto-al-valor-agregado/ | N27: Servicio/tema general para contribuyentes
A28: Pequeños Contribuyentes | B28: Pequeño Contribuyente | D28: Regímenes tributarios | E28: Pequeño Contribuyente | F28: Consulta NIT de Pequeño Contribuyente | G28: Consultar si un NIT es Pequeño Contribuyente | H28: Servicio en línea para consultar si un NIT es Pequeño Contribuyente. | J28: Análisis | K28: Régimen de Pequeño Contribuyente (Ley del IVA) | L28: SERVICIOS TRIBUTARIOS | M28: https://portal.sat.gob.gt/portal/consulta-regimen-de-pequeno-contribuyente/ | N28: Servicio/tema general para contribuyentes
A29: Pequeños Contribuyentes | B29: Pequeño Contribuyente | D29: Regímenes tributarios | E29: Pequeño Contribuyente | F29: Régimen Electrónico de Pequeño Contribuyente | G29: Curso: Régimen Electrónico de Pequeño Contribuyente | H29: Capacitación virtual de la SAT sobre Régimen Electrónico de Pequeño Contribuyente. | J29: Análisis | K29: Régimen de Pequeño Contribuyente (Ley del IVA) | L29: CAPACITACIÓN | M29: https://sites.google.com/capacitacionessat.page/cultura-tributariad/cursos-virtuales-sat/impuesto-al-valor-agregado-iva/r%C3%A9gimen-electr%C3%B3nico-de-peque%C3%B1o-contribuyente | N29: Servicio/tema general para contribuyentes
A30: Pequeños Contribuyentes | B30: Pequeño Contribuyente | D30: Regímenes tributarios | E30: Pequeño Contribuyente | F30: Régimen Electrónico del Pequeño Contribuyente | G30: Curso: Régimen Electrónico de Pequeño Contribuyente | H30: Capacitación virtual de la SAT sobre Régimen Electrónico de Pequeño Contribuyente. | J30: Análisis | K30: Régimen de Pequeño Contribuyente (Ley del IVA) | L30: CAPACITACIÓN | M30: https://sites.google.com/capacitacionessat.page/eventosenvivo/p%C3%A1gina-principal/r%C3%A9gimen-electr%C3%B3nico-del-peque%C3%B1o-contribuyente | N30: Servicio/tema general para contribuyentes
A31: Pequeños Contribuyentes | B31: Pequeño Contribuyente | D31: Regímenes tributarios | E31: Pequeño Contribuyente | F31: Régimen del pequeño contribuyente | G31: Curso: régimen de Pequeño Contribuyente | H31: Capacitación virtual de la SAT sobre régimen de Pequeño Contribuyente. | J31: Análisis | K31: Régimen de Pequeño Contribuyente (Ley del IVA) | L31: CAPACITACIÓN | M31: https://sites.google.com/capacitacionessat.page/cultura-tributariad/cursos-virtuales-sat/impuesto-al-valor-agregado/r%C3%A9gimen-del-peque%C3%B1o-contribuyente | N31: Servicio/tema general para contribuyentes
A32: Pequeños Contribuyentes | B32: Primario | D32: Consultas y verificadores | E32: Registros públicos | F32: Productores Inscritos: Consulta Productores | G32: Consultar productores inscritos | H32: Servicio en línea para consultar productores inscritos. | J32: Análisis | K32: Registro de productores | L32: SERVICIOS TRIBUTARIOS | M32: https://portal.sat.gob.gt/portal/consulta-productores/ | N32: Servicio/tema general para contribuyentes
A33: Pequeños Contribuyentes | B33: Primario | D33: Cultura tributaria y capacitación | E33: Cursos por tipo de contribuyente | F33: Productores de Productos Agropecuarios, Artesanales y Reciclados | G33: Curso: productores agropecuarios, artesanales y de reciclaje | H33: Capacitación virtual de la SAT sobre productores agropecuarios, artesanales y de reciclaje. | J33: Análisis | K33: Régimen agropecuario (Decreto 31-2024) | L33: CAPACITACIÓN | M33: https://sites.google.com/capacitacionessat.page/cultura-tributariad/cursos-virtuales-sat/impuesto-al-valor-agregado-iva/inscripci%C3%B3n-y-actualizaci%C3%B3n-de-productores | N33: Servicio/tema general para contribuyentes
... A42: Pequeños Contribuyentes | B42: Pecuario | D42: Regímenes tributarios | E42: Régimen Agropecuario | F42: Principales obligaciones tributarias del Régimen especial de Contribuyente Agropecuario (Convencional y Electrónico) | G42: Curso: obligaciones del Régimen Especial Agropecuario | H42: Capacitación virtual de la SAT sobre obligaciones del Régimen Especial Agropecuario. | J42: Análisis | K42: Régimen agropecuario (Decreto 31-2024) | L42: CAPACITACIÓN | M42: https://sites.google.com/capacitacionessat.page/cultura-tributariad/cursos-virtuales-sat/impuesto-al-valor-agregado-iva/principales-obligaciones-tributarias-del-r%C3%A9gimen-especial-de-contribuyente | N42: Servicio/tema general para contribuyentes
A43: Contribuyente General | B43: Todos los grupos | D43: Facturación electrónica y documentos tributarios | E43: Constancias de exención (CIVA y CAIS) | F43: Emisión Constancias de Adquisición de Insumos y Servicios -CAIS- | G43: Emitir constancias CAIS | H43: Requisitos, pasos y documentos para emitir constancias CAIS. | I43: Contribuyente General | J43: Grupos y categorías | K43: Marcada «SI» en el archivo Grupos y categorías | L43: SERVICIOS TRIBUTARIOS | M43: https://portal.sat.gob.gt/portal/emision-constancias-de-adquisicion-de-insumos-y-servicios-cais/ | N43: Servicio/tema general para contribuyentes
A44: Contribuyente General | B44: Todos los grupos | D44: Facturación electrónica y documentos tributarios | E44: Constancias de exención (CIVA y CAIS) | F44: Emisión Constancias de Exención de IVA -CIVA- | G44: Emitir constancias de exención de IVA (CIVA) | H44: Requisitos, pasos y documentos para emitir constancias de exención de IVA (CIVA). | I44: Contribuyente General | J44: Grupos y categorías | K44: Marcada «SI» en el archivo Grupos y categorías | L44: SERVICIOS TRIBUTARIOS | M44: https://portal.sat.gob.gt/portal/emision-constancias-de-exencion-de-iva-civa/ | N44: Servicio/tema general para contribuyentes
A45: Contribuyente General | B45: Todos los grupos | D45: Otros servicios al contribuyente | E45: Constancias y gestiones del RTU | F45: Requisitos de persona/empresa | G45: Requisitos para Abogados y Notarios | H45: Requisitos, listado de pasos, y casos especiales; para la inscripción/actualización, activación, confirmación de huella y Venta de Especies Fiscales para Abogados y Notarios. | I45: Contribuyente General | J45: Grupos y categorías | K45: Marcada «SI» en el archivo Grupos y categorías | L45: SERVICIOS TRIBUTARIOS | M45: https://portal.sat.gob.gt/portal/requisitos-de-personas-empresas/ | N45: Servicio/tema general para contribuyentes
A46: Contribuyente General | B46: Contribuyente General | D46: Consultas y verificadores | E46: Autorización y consulta | F46: Autorización de Máquinas en Agencia Virtual | G46: Autorizar máquinas registradoras en Agencia Virtual | H46: Requisitos, pasos y documentos para autorizar máquinas registradoras en Agencia Virtual. | J46: Análisis | K46: Máquinas registradoras | L46: SERVICIOS TRIBUTARIOS | M46: https://portal.sat.gob.gt/portal/requisitos-tramites-agencias/autorizacion-de-maquinas-en-agencia-virtual/ | N46: Servicio/tema general para contribuyentes
A47: Contribuyente General | B47: Contribuyente General | D47: Consultas y verificadores | E47: Autorización y consulta | F47: Consulta Autorización de Máquina | G47: Consultar si una máquina registradora está autorizada | H47: Servicio en línea para consultar si una máquina registradora está autorizada. | J47: Análisis | K47: Máquinas registradoras | L47: SERVICIOS TRIBUTARIOS | M47: https://portal.sat.gob.gt/portal/consulta-autorizacion-de-maquina/ | N47: Servicio/tema general para contribuyentes
A48: Contribuyente General | B48: Contribuyente General | D48: Cultura tributaria y capacitación | E48: Cursos por impuesto | F48: Regímenes para las Rentas de Actividades Lucrativas | G48: Curso: regímenes del ISR para negocios | H48: Capacitación virtual de la SAT sobre regímenes del ISR para negocios. | J48: Análisis | K48: Régimen General del IVA e ISR de actividades lucrativas | L48: CAPACITACIÓN | M48: https://sites.google.com/capacitacionessat.page/cultura-tributariad/cursos-virtuales-sat/impuesto-sobre-la-renta/reg%C3%ADmenes-para-las-rentas-de-actividades-lucrativas | N48: Servicio/tema general para contribuyentes
A49: Contribuyente General | B49: Contribuyente General | D49: Devoluciones y créditos fiscales | E49: ISR (Impuesto Sobre la Renta) | F49: Formulario Electrónico SAT-2350 (versión vigente) Solicitud de Devolución de Pagos en Exceso del ISR Anual | G49: Devolución de ISR anual pagado de más | H49: Información sobre: Devolución de ISR anual pagado de más. | J49: Análisis | K49: Devoluciones de ISR/IVA/ISO de actividades lucrativas | L49: SERVICIOS TRIBUTARIOS | M49: https://portal.sat.gob.gt/portal/requisitos-tramites-agencias/formulario-electronico-sat-2350-version-vigente-solicitud-de-pagos-en-exceso/ | N49: Servicio/tema general para contribuyentes
...

Sheet Operadores de comercio exterior
A1: Operadores de comercio exterior
A2: Importadores, exportadores y auxiliares de la función pública aduanera que intervienen en operaciones de comercio exterior. Orden: Categoría › Grupo › Tema › Página. «Todos los grupos» = la usan todos los grupos de la categoría. «Trámites comunes» = la usan varias categorías.
A4: Macro-Grupo | B4: Actor / Rol | C4: Especialidad / Tema | D4: Área Funcional (Subtema) | E4: Nombre del Trámite | F4: Descripción (Lenguaje Ciudadano Activo) | G4: Control de Auditoría | H4: Etapa Ciclo ATO | I4: Tipo de Interacción | J4: Es Brecha | K4: Ruta de Navegación (Miga de Pan) | L4: URL Oficial SAT | M4: Notas / Justificación
A5: 2. Auxiliares de la Función Pública Aduanera (AFPA) | B5: Apoderados Especiales Aduaneros | C5: Apoderados Especiales Aduaneros | D5: Registro y acreditación | E5: Requisitos para la renovación de operación de auxiliares de la función pública | F5: Presenta la solicitud y cumple los requisitos oficiales ante la SAT para renovar tu autorización anual como Apoderados Especiales Aduaneros. | G5: APROBADO | H5: Empezar y registrarse | I5: Trámite / Aplicativo en Línea | J5: NO | K5: Operadores de Comercio Exterior > 2. Auxiliares de la Función Pública Aduanera (AFPA) > Apoderados Especiales Aduaneros > Registro y acreditación > Requisitos para la renovación de operación de auxiliares de la función pública | L5: https://portal.sat.gob.gt/portal/requisitos-de-aduanas/#1608063945646-f9ebd644-65ff
A6: 2. Auxiliares de la Función Pública Aduanera (AFPA) | B6: Apoderados Especiales Aduaneros | C6: Apoderados Especiales Aduaneros | D6: Registro y acreditación | E6: Auxiliares de la función pública aduanera (Carné, componente ActiveX PKI/DUA) | F6: Gestiona la emisión y actualización de tu carné oficial de identificación para ingresar a recintos aduaneros. | G6: APROBADO | H6: Empezar y registrarse | I6: Descarga de Documento / Software | J6: NO | K6: Operadores de Comercio Exterior > 2. Auxiliares de la Función Pública Aduanera (AFPA) > Apoderados Especiales Aduaneros > Registro y acreditación > Auxiliares de la función pública aduanera (Carné, componente ActiveX PKI/DUA) | L6: https://portal.sat.gob.gt/portal/procedimientos-aduanas/#1570112086149-de895ac7-a87c
A7: 2. Auxiliares de la Función Pública Aduanera (AFPA) | B7: Apoderados Especiales Aduaneros | C7: Apoderados Especiales Aduaneros | D7: Registro y acreditación | E7: Recepción de seguro de caución importación y admisión temporal | F7: Entrega y registra la póliza de fianza o seguro de caución exigido para garantizar tus operaciones aduaneras. | G7: APROBADO | H7: Empezar y registrarse | I7: Trámite / Aplicativo en Línea | J7: NO | K7: Operadores de Comercio Exterior > 2. Auxiliares de la Función Pública Aduanera (AFPA) > Apoderados Especiales Aduaneros > Registro y acreditación > Recepción de seguro de caución importación y admisión temporal | L7: https://portal.sat.gob.gt/portal/requisitos-tramites-agencias/recepcion-de-seguro-de-caucion-importacion-y-admision-temporal/
A8: 2. Auxiliares de la Función Pública Aduanera (AFPA) | B8: Apoderados Especiales Aduaneros | C8: Apoderados Especiales Aduaneros | D8: Registro y acreditación | E8: Solvencia fiscal (Requisito para renovación AFPA) | F8: Obtén tu solvencia fiscal en línea como requisito indispensable para operar y renovar tu acreditación como Apoderados Especiales Aduaneros. | G8: APROBADO | H8: Empezar y registrarse | I8: Trámite / Aplicativo en Línea | J8: NO | K8: Operadores de Comercio Exterior > 2. Auxiliares de la Función Pública Aduanera (AFPA) > Apoderados Especiales Aduaneros > Registro y acreditación > Solvencia fiscal (Requisito para renovación AFPA) | L8: https://portal.sat.gob.gt/portal/solvencia-fiscal/
A9: 2. Auxiliares de la Función Pública Aduanera (AFPA) | B9: Apoderados Especiales Aduaneros | C9: Apoderados Especiales Aduaneros | D9: Registro y acreditación | E9: Autorización inicial y registro de mandato de apoderado especial | F9: Presenta el mandato legal y solicita la autorización inicial ante la SAT para actuar como apoderado especial aduanero. | G9: PENDIENTE (Propuesta brecha) | H9: Empezar y registrarse | I9: Trámite / Aplicativo en Línea | J9: SÍ | K9: Operadores de Comercio Exterior > 2. Auxiliares de la Función Pública Aduanera (AFPA) > Apoderados Especiales Aduaneros > Registro y acreditación > Autorización inicial y registro de mandato de apoderado especial | L9: https://portal.sat.gob.gt/portal/requisitos-de-aduanas/ | M9: Propuesta de brecha normativa identificada para mesa técnica SAT.
A10: 2. Auxiliares de la Función Pública Aduanera (AFPA) | B10: Apoderados Especiales Aduaneros | C10: Apoderados Especiales Aduaneros | D10: Operaciones y trámites | E10: Declaración de mercancías (DUCA y Aduana sin papeles) | F10: Transmite electrónicamente la declaración de mercancías DUCA y gestiona el despacho aduanero ágil. | G10: APROBADO | H10: Operación y declaraciones | I10: Trámite / Aplicativo en Línea | J10: NO | K10: Operadores de Comercio Exterior > 2. Auxiliares de la Función Pública Aduanera (AFPA) > Apoderados Especiales Aduaneros > Operaciones y trámites > Declaración de mercancías (DUCA y Aduana sin papeles) | L10: https://portal.sat.gob.gt/portal/procedimientos-aduanas/
A11: 2. Auxiliares de la Función Pública Aduanera (AFPA) | B11: Apoderados Especiales Aduaneros | C11: Apoderados Especiales Aduaneros | D11: Operaciones y trámites | E11: Declaración anticipada | F11: Presenta tu declaración y paga tributos antes de que arribe el medio de transporte para agilizar el levante. | G11: APROBADO | H11: Operación y declaraciones | I11: Trámite / Aplicativo en Línea | J11: NO | K11: Operadores de Comercio Exterior > 2. Auxiliares de la Función Pública Aduanera (AFPA) > Apoderados Especiales Aduaneros > Operaciones y trámites > Declaración anticipada | L11: https://portal.sat.gob.gt/portal/facilitacion-de-comercio/#1559325573466-1284efd5-2d1b
A12: 2. Auxiliares de la Función Pública Aduanera (AFPA) | B12: Apoderados Especiales Aduaneros | C12: Apoderados Especiales Aduaneros | D12: Operaciones y trámites | E12: Sistema de franquicias electrónicas | F12: Aplica en línea a franquicias aduaneras para gestionar la exención o exoneración de tributos autorizados. | G12: APROBADO | H12: Operación y declaraciones | I12: Trámite / Aplicativo en Línea | J12: NO | K12: Operadores de Comercio Exterior > 2. Auxiliares de la Función Pública Aduanera (AFPA) > Apoderados Especiales Aduaneros > Operaciones y trámites > Sistema de franquicias electrónicas | L12: https://portal.sat.gob.gt/portal/franquicias-electronicas/
A13: 2. Auxiliares de la Función Pública Aduanera (AFPA) | B13: Apoderados Especiales Aduaneros | C13: Apoderados Especiales Aduaneros | D13: Consultas y seguimiento | E13: Consultas de aduanas (Rampa de revisión, revisores, retención/liberación, arancel) | F13: Consulta los aranceles DAI, gravámenes e impuestos del SAC y verifica los permisos no arancelarios exigibles. | G13: APROBADO | H13: Consultas y herramientas | I13: Consulta en Base de Datos | J13: NO | K13: Operadores de Comercio Exterior > 2. Auxiliares de la Función Pública Aduanera (AFPA) > Apoderados Especiales Aduaneros > Consultas y seguimiento > Consultas de aduanas (Rampa de revisión, revisores, retención/liberación, arancel) | L13: https://portal.sat.gob.gt/portal/consultas-aduanas/
A14: 2. Auxiliares de la Función Pública Aduanera (AFPA) | B14: Apoderados Especiales Aduaneros | C14: Apoderados Especiales Aduaneros | D14: Consultas y seguimiento | E14: Requisitos para consulta de expedientes de gestión aduanera | F14: Da seguimiento al estado de avance y resolución del expediente administrativo de tu gestión aduanera. | G14: APROBADO | H14: Consultas y herramientas | I14: Consulta en Base de Datos | J14: NO | K14: Operadores de Comercio Exterior > 2. Auxiliares de la Función Pública Aduanera (AFPA) > Apoderados Especiales Aduaneros > Consultas y seguimiento > Requisitos para consulta de expedientes de gestión aduanera | L14: https://portal.sat.gob.gt/portal/requisitos-de-aduanas/#1542142398181-8db4844a-6760
A15: 2. Auxiliares de la Función Pública Aduanera (AFPA) | B15: Apoderados Especiales Aduaneros | C15: Apoderados Especiales Aduaneros | D15: Consultas y seguimiento | E15: Unión aduanera (Procedimientos y resoluciones) | F15: Consulta los criterios de clasificación arancelaria y resoluciones anticipadas emitidas por la Intendencia de Aduanas. | G15: APROBADO | H15: Consultas y herramientas | I15: Trámite / Aplicativo en Línea | J15: NO | K15: Operadores de Comercio Exterior > 2. Auxiliares de la Función Pública Aduanera (AFPA) > Apoderados Especiales Aduaneros > Consultas y seguimiento > Unión aduanera (Procedimientos y resoluciones) | L15: https://portal.sat.gob.gt/portal/union-aduanera/
A16: 2. Auxiliares de la Función Pública Aduanera (AFPA) | B16: Apoderados Especiales Aduaneros | C16: Apoderados Especiales Aduaneros | D16: Normativa y recursos | E16: Procedimientos, instructivos, manuales y guías para gestiones aduaneras | F16: Desconsolida conocimientos de embarque y guías aéreas hijas para entregar bultos a sus consignatarios. | G16: APROBADO | H16: Normativa y asistencia | I16: Guía Informativa / Texto | J16: NO | K16: Operadores de Comercio Exterior > 2. Auxiliares de la Función Pública Aduanera (AFPA) > Apoderados Especiales Aduaneros > Normativa y recursos > Procedimientos, instructivos, manuales y guías para gestiones aduaneras | L16: https://portal.sat.gob.gt/portal/procedimientos-aduanas/#1571412473853-2ed0b43f-287f
A17: 2. Auxiliares de la Función Pública Aduanera (AFPA) | B17: Apoderados Especiales Aduaneros | C17: Apoderados Especiales Aduaneros | D17: Normativa y recursos | E17: Procedimientos administrativos de aduanas (Sanciones y recursos) | F17: Conoce el régimen de infracciones aduaneras y los procedimientos para interponer recursos de revocatoria. | G17: APROBADO | H17: Normativa y asistencia | I17: Guía Informativa / Texto | J17: NO | K17: Operadores de Comercio Exterior > 2. Auxiliares de la Función Pública Aduanera (AFPA) > Apoderados Especiales Aduaneros > Normativa y recursos > Procedimientos administrativos de aduanas (Sanciones y recursos) | L17: https://portal.sat.gob.gt/portal/procedimientos-aduanas/#1570112033454-be3581a4-383a
A18: 2. Auxiliares de la Función Pública Aduanera (AFPA) | B18: Apoderados Especiales Aduaneros | C18: Apoderados Especiales Aduaneros | D18: Normativa y recursos | E18: Legislación aduanera (Biblioteca en línea SAT) | F18: Descarga y consulta el marco legal, leyes nacionales, CAUCA y RECAUCA aplicables a Apoderados Especiales Aduaneros. | G18: APROBADO | H18: Normativa y asistencia | I18: Guía Informativa / Texto | J18: NO | K18: Operadores de Comercio Exterior > 2. Auxiliares de la Función Pública Aduanera (AFPA) > Apoderados Especiales Aduaneros > Normativa y recursos > Legislación aduanera (Biblioteca en línea SAT) | L18: https://portal.sat.gob.gt/portal/biblioteca-en-linea-sat/legislacion-aduanera/
A19: 2. Auxiliares de la Función Pública Aduanera (AFPA) | B19: Apoderados Especiales Aduaneros | C19: Apoderados Especiales Aduaneros | D19: Normativa y recursos | E19: Preguntas frecuentes sobre temas aduaneros | F19: Resuelve dudas frecuentes sobre normativa, requisitos y procedimientos aduaneros oficiales. | G19: APROBADO | H19: Normativa y asistencia | I19: Guía Informativa / Texto | J19: NO | K19: Operadores de Comercio Exterior > 2. Auxiliares de la Función Pública Aduanera (AFPA) > Apoderados Especiales Aduaneros > Normativa y recursos > Preguntas frecuentes sobre temas aduaneros | L19: https://portal.sat.gob.gt/portal/preguntas-frecuentes/temas-aduaneros/
A20: 2. Auxiliares de la Función Pública Aduanera (AFPA) | B20: Apoderados Especiales Aduaneros | C20: Apoderados Especiales Aduaneros | D20: Normativa y recursos | E20: Capacitaciones para auxiliares de la función pública | F20: Inscríbete en capacitaciones, talleres y diplomados aduaneros impartidos por la SAT para Apoderados Especiales Aduaneros. | G20: APROBADO | H20: Normativa y asistencia | I20: Guía Informativa / Texto | J20: NO | K20: Operadores de Comercio Exterior > 2. Auxiliares de la Función Pública Aduanera (AFPA) > Apoderados Especiales Aduaneros > Normativa y recursos > Capacitaciones para auxiliares de la función pública | L20: https://portal.sat.gob.gt/portal/#capacitacion
A21: 2. Auxiliares de la Función Pública Aduanera (AFPA) | B21: Depósitos Aduaneros | C21: Almacenes Fiscales | D21: Registro y acreditación | E21: Requisitos para la renovación de operación de auxiliares de la función pública | F21: Presenta la solicitud y cumple los requisitos oficiales ante la SAT para renovar tu autorización anual como Depósitos Aduaneros. | G21: APROBADO | H21: Empezar y registrarse | I21: Trámite / Aplicativo en Línea | J21: NO | K21: Operadores de Comercio Exterior > 2. Auxiliares de la Función Pública Aduanera (AFPA) > Depósitos Aduaneros > Almacenes Fiscales > Registro y acreditación > Requisitos para la renovación de operación de auxiliares de la función pública | L21: https://portal.sat.gob.gt/portal/requisitos-de-aduanas/#1608063945646-f9ebd644-65ff
... A24: 2. Auxiliares de la Función Pública Aduanera (AFPA) | B24: Depósitos Aduaneros | C24: Almacenes Fiscales | D24: Registro y acreditación | E24: Solvencia fiscal (Requisito indispensable de renovación AFPA) | F24: Obtén tu solvencia fiscal en línea como requisito indispensable para operar y renovar tu acreditación como Depósitos Aduaneros. | G24: APROBADO | H24: Empezar y registrarse | I24: Trámite / Aplicativo en Línea | J24: NO | K24: Operadores de Comercio Exterior > 2. Auxiliares de la Función Pública Aduanera (AFPA) > Depósitos Aduaneros > Almacenes Fiscales > Registro y acreditación > Solvencia fiscal (Requisito indispensable de renovación AFPA) | L24: https://portal.sat.gob.gt/portal/solvencia-fiscal/
A25: 2. Auxiliares de la Función Pública Aduanera (AFPA) | B25: Depósitos Aduaneros | C25: Almacenes Fiscales | D25: Registro y acreditación | E25: Requisitos para habilitación y ampliación de recintos de depósito fiscal | F25: Gestiona los requisitos y autorizaciones técnicas ante la SAT para habilitar o ampliar recintos de depósito fiscal. | G25: PENDIENTE (Propuesta brecha) | H25: Empezar y registrarse | I25: Trámite / Aplicativo en Línea | J25: SÍ | K25: Operadores de Comercio Exterior > 2. Auxiliares de la Función Pública Aduanera (AFPA) > Depósitos Aduaneros > Almacenes Fiscales > Registro y acreditación > Requisitos para habilitación y ampliación de recintos de depósito fiscal | L25: https://portal.sat.gob.gt/portal/requisitos-de-aduanas/ | M25: Propuesta de brecha normativa identificada para mesa técnica SAT.
A26: 2. Auxiliares de la Función Pública Aduanera (AFPA) | B26: Depósitos Aduaneros | C26: Almacenes Fiscales | D26: Operaciones y trámites | E26: Procedimientos, instructivos y guías para gestiones aduaneras de depósito | F26: Desconsolida conocimientos de embarque y guías aéreas hijas para entregar bultos a sus consignatarios. | G26: APROBADO | H26: Operación y declaraciones | I26: Guía Informativa / Texto | J26: NO | K26: Operadores de Comercio Exterior > 2. Auxiliares de la Función Pública Aduanera (AFPA) > Depósitos Aduaneros > Almacenes Fiscales > Operaciones y trámites > Procedimientos, instructivos y guías para gestiones aduaneras de depósito | L26: https://portal.sat.gob.gt/portal/procedimientos-aduanas/#1571412473853-2ed0b43f-287f
A27: 2. Auxiliares de la Función Pública Aduanera (AFPA) | B27: Depósitos Aduaneros | C27: Almacenes Fiscales | D27: Operaciones y trámites | E27: Declaración de mercancías (DUCA, tránsitos y aduana sin papeles) | F27: Transmite electrónicamente la declaración de mercancías DUCA y gestiona el despacho aduanero ágil. | G27: APROBADO | H27: Operación y declaraciones | I27: Trámite / Aplicativo en Línea | J27: NO | K27: Operadores de Comercio Exterior > 2. Auxiliares de la Función Pública Aduanera (AFPA) > Depósitos Aduaneros > Almacenes Fiscales > Operaciones y trámites > Declaración de mercancías (DUCA, tránsitos y aduana sin papeles) | L27: https://portal.sat.gob.gt/portal/procedimientos-aduanas/
A28: 2. Auxiliares de la Función Pública Aduanera (AFPA) | B28: Depósitos Aduaneros | C28: Almacenes Fiscales | D28: Operaciones y trámites | E28: Programa de modernización integral aduanera (MIAD) | F28: Conoce los lineamientos y avances del Programa de Modernización Integral Aduanera (MIAD) de la SAT. | G28: APROBADO | H28: Operación y declaraciones | I28: Guía Informativa / Texto | J28: NO | K28: Operadores de Comercio Exterior > 2. Auxiliares de la Función Pública Aduanera (AFPA) > Depósitos Aduaneros > Almacenes Fiscales > Operaciones y trámites > Programa de modernización integral aduanera (MIAD) | L28: https://portal.sat.gob.gt/portal/programa-miad/
A29: 2. Auxiliares de la Función Pública Aduanera (AFPA) | B29: Depósitos Aduaneros | C29: Almacenes Fiscales | D29: Operaciones y trámites | E29: Transmisión y control de inventarios bajo régimen de depósito aduanero | F29: Transmite los movimientos de entrada y salida para el control de inventarios de mercancías bajo régimen de depósito aduanero. | G29: PENDIENTE (Propuesta brecha) | H29: Operación y declaraciones | I29: Consulta en Base de Datos | J29: SÍ | K29: Operadores de Comercio Exterior > 2. Auxiliares de la Función Pública Aduanera (AFPA) > Depósitos Aduaneros > Almacenes Fiscales > Operaciones y trámites > Transmisión y control de inventarios bajo régimen de depósito aduanero | L29: https://portal.sat.gob.gt/portal/procedimientos-aduanas/ | M29: Propuesta de brecha normativa identificada para mesa técnica SAT.
A30: 2. Auxiliares de la Función Pública Aduanera (AFPA) | B30: Depósitos Aduaneros | C30: Almacenes Fiscales | D30: Consultas y seguimiento | E30: Consultas de aduanas (Retención, liberación, rampa y control de permanencia) | F30: Consulta el estado público de retención o liberación de mercancías en recintos portuarios y aduaneros. | G30: APROBADO | H30: Consultas y herramientas | I30: Consulta en Base de Datos | J30: NO | K30: Operadores de Comercio Exterior > 2. Auxiliares de la Función Pública Aduanera (AFPA) > Depósitos Aduaneros > Almacenes Fiscales > Consultas y seguimiento > Consultas de aduanas (Retención, liberación, rampa y control de permanencia) | L30: https://portal.sat.gob.gt/portal/consultas-aduanas/
A31: 2. Auxiliares de la Función Pública Aduanera (AFPA) | B31: Depósitos Aduaneros | C31: Almacenes Fiscales | D31: Consultas y seguimiento | E31: Requisitos para consulta de expedientes de gestión aduanera | F31: Da seguimiento al estado de avance y resolución del expediente administrativo de tu gestión aduanera. | G31: APROBADO | H31: Consultas y herramientas | I31: Consulta en Base de Datos | J31: NO | K31: Operadores de Comercio Exterior > 2. Auxiliares de la Función Pública Aduanera (AFPA) > Depósitos Aduaneros > Almacenes Fiscales > Consultas y seguimiento > Requisitos para consulta de expedientes de gestión aduanera | L31: https://portal.sat.gob.gt/portal/requisitos-de-aduanas/#1542142398181-8db4844a-6760
A32: 2. Auxiliares de la Función Pública Aduanera (AFPA) | B32: Depósitos Aduaneros | C32: Almacenes Fiscales | D32: Consultas y seguimiento | E32: Consulta y facilidades de pago de convenios tributarios | F32: Consulta el estado de cuotas y facilidades de pago autorizadas bajo convenios tributarios ante la SAT. | G32: APROBADO | H32: Consultas y herramientas | I32: Consulta en Base de Datos | J32: NO | K32: Operadores de Comercio Exterior > 2. Auxiliares de la Función Pública Aduanera (AFPA) > Depósitos Aduaneros > Almacenes Fiscales > Consultas y seguimiento > Consulta y facilidades de pago de convenios tributarios | L32: https://portal.sat.gob.gt/portal/consulta-movimiento-convenio/
