Workbook

Sheet Resumen Ejecutivo
B2: SUPERINTENDENCIA DE ADMINISTRACIÓN TRIBUTARIA — SAT GUATEMALA
B4: CATÁLOGO DESACOPLADO DE CONTENIDOS Y GESTIONES ÚNICAS (CONTENT HUB)
B6: =COUNTA('Catálogo Único (683)'!A2:A684) | C6: =SUM('Catálogo Único (683)'!O2:O684) | E6: =COUNTIF('Catálogo Único (683)'!N2:N684, "NO") | F6: =COUNTIF('Catálogo Único (683)'!N2:N684, "SÍ") | H6: =COUNTIF('Catálogo Único (683)'!Q2:Q684, "SÍ")
B9: 1. DISTRIBUCIÓN POR ETAPA DEL CICLO DE VIDA DE LA GESTIÓN
B10: No. | C10: Etapa del Ciclo de Vida | D10: Descripción Operativa | E10: Total Contenidos | F10: % del Catálogo
B11: 1 | C11: Operar y Declarar | D11: Rutina tributaria, declaraciones mensuales/anuales, pagos y transmisiones DUCA. | E11: =COUNTIF('Catálogo Único (683)'!G2:G684, "Operar y Declarar") | F11: =E11/E16
B12: 2 | C12: Modificar y Cerrar | D12: Actualizaciones de RTU, traspasos, ceses prescritos y renovación anual de fianzas. | E12: =COUNTIF('Catálogo Único (683)'!G2:G684, "Modificar y Cerrar") | F12: =E12/E16
B13: 3 | C13: Normativa y Asistencia | D13: Marco legal, resoluciones, criterios tributarios/aduaneros y capacitaciones virtuales. | E13: =COUNTIF('Catálogo Único (683)'!G2:G684, "Normativa y Asistencia") | F13: =E13/E16
B14: 4 | C14: Consultas y Herramientas | D14: Verificadores abiertos, solvencia fiscal, consulta de NIT y selectivo aduanero. | E14: =COUNTIF('Catálogo Único (683)'!G2:G684, "Consultas y Herramientas") | F14: =E14/E16
B15: 5 | C15: Empezar y Registrarse | D15: Inscripción inicial de NIT, padrones, carnés de auxiliares y habilitación de usuario. | E15: =COUNTIF('Catálogo Único (683)'!G2:G684, "Empezar y Registrarse") | F15: =E15/E16
C16: TOTAL CATÁLOGO | E16: =SUM(E11:E15) | F16: =SUM(F11:F15)
B18: 2. MODELO DE POLIJERARQUÍA (FRECUENCIA DE APARICIÓN EN EL ÁRBOL)
B19: Frecuencia de Aparición | C19: Condición Arquitectónica | D19: Cantidad de Contenidos | E19: Nodos que Aporta | F19: % de Contenidos
B20: Aparece 1 sola vez | C20: Contenido exclusivo de una categoría o rol específico | D20: =COUNTIF('Catálogo Único (683)'!O2:O684, 1) | E20: =D20*1 | F20: =D20/D25
B21: Aparece 2 veces | C21: Contenido compartido entre 2 subramas o segmentos | D21: =COUNTIF('Catálogo Único (683)'!O2:O684, 2) | E21: =D21*2 | F21: =D21/D25
B22: Aparece 3 veces | C22: Herramienta o trámite común para 3 ramas | D22: =COUNTIF('Catálogo Único (683)'!O2:O684, 3) | E22: =D22*3 | F22: =D22/D25
B23: Aparece 4 veces | C23: Recurso transversal para 4 actores de comercio exterior | D23: =COUNTIF('Catálogo Único (683)'!O2:O684, 4) | E23: =D23*4 | F23: =D23/D25
B24: Aparece 5 veces | C24: Recurso transversal para los 5 Auxiliares de la Función Pública | D24: =COUNTIF('Catálogo Único (683)'!O2:O684, 5) | E24: =D24*5 | F24: =D24/D25
B25: TOTAL CATÁLOGO | C25: Suma de contenidos únicos y total de nodos del árbol | D25: =SUM(D20:D24) | E25: =SUM(E20:E24) | F25: =SUM(F20:F24)

Sheet Catálogo Único (683)
A1: No. | B1: Código Canónico Oficial (SAT-GES-####) | C1: ID Content Hub | D1: Nombre de la Gestión / Contenido (Lenguaje Claro) | E1: Nombre Oficial Administrativo | F1: ¿Para qué sirve? (Descripción Operativa) | G1: Etapa del Ciclo de Vida | H1: Tipo de Interacción | I1: Tipología de Contenido | J1: Plataforma / Sistema Técnico | K1: Canal de Atención | L1: Perfil Destinatario | M1: Base Legal / Fundamento Jurídico | N1: ¿Es Transversal? | O1: Total Audiencias / Nodos | P1: Segmentos Aplicables | Q1: ¿Es Brecha Normativa? | R1: URL Portal SAT | S1: Familia Temática
A2: 1 | B2: SAT-GES-0001 | C2: cnt-SAT-GES-0001 | D2: Solicitar Número de Identificación Tributaria (NIT) | E2: Solicitar Número de Identificación Tributaria (NIT) | F2: Cómo solicitar un Número de Identificación Tributaria (NIT), actualizar sus datos, consultar su NIT y qué hacer si ha sido utilizado de forma indebida. | G2: Empezar y registrarse | H2: Guía Informativa / Texto | I2: Guía de Requisitos y Pasos | J2: Portal Web SAT | K2: Presencial / Mixto | L2: Personas Individuales (Nacionales y Extranjeros sin actividad económica) | M2: Código Tributario, Decreto 6-91 (Arts. 112 y 120) y Acuerdo de Directorio SAT 08-2020. | N2: NO | O2: 1 | P2: contribuyentes | Q2: NO | R2: https://portal.sat.gob.gt/portal/requisitos-de-personas-empresas/#1615485066841-639e67c5-51e3 | S2: FAM-03 Registro Tributario Unificado (RTU) Digital
A3: 2 | B3: SAT-GES-0002 | C3: cnt-SAT-GES-0002 | D3: Actualización de Datos y Transición de Régimen | E3: Requisitos para la Actualización en el Registro Tributario Unificado (RTU) | F3: Actualiza tus datos personales en el Registro Tributario Unificado (RTU) o solicita el paso formal al régimen con negocio cuando inicies actividades económicas. | G3: Modificaciones y cierre | H3: Guía Informativa / Texto | I3: Guía de Requisitos y Pasos | J3: Portal Web SAT | K3: Presencial / Mixto | L3: Personas que inician relación laboral o comercial | M3: Código Tributario, Decreto 6-91 (Arts. 112 y 120) y Acuerdo de Directorio SAT 08-2020. | N3: NO | O3: 1 | P3: contribuyentes | Q3: NO | R3: https://portal.sat.gob.gt/portal/requisitos-de-personas-empresas/#1541621044169-4198d06d-693f | S3: FAM-03 Registro Tributario Unificado (RTU) Digital
A4: 3 | B4: SAT-GES-0003 | C4: cnt-SAT-GES-0003 | D4: Solicitud y Activación de Agencia Virtual | E4: Agencia Virtual | F4: Acceso a la plataforma web de la SAT para consultar datos personales y descargar tu constancia del Registro Tributario Unificado (RTU). | G4: Operación y declaraciones | H4: Trámite / Aplicativo en Línea | I4: Trámite Transaccional | J4: Agencia Virtual SAT | K4: 100% Digital | L4: Usuarios registrados con NIT | M4: Código Tributario, Decreto 6-91 (Arts. 112 y 120) y Acuerdo de Directorio SAT 08-2020. | N4: NO | O4: 1 | P4: contribuyentes | Q4: NO | R4: https://farm3.sat.gob.gt/menu/login.jsf | S4: FAM-03 Registro Tributario Unificado (RTU) Digital; FAM-05 Solvencias y Convenios de Pago; FAM-09 Agencia Virtual y Servicios Remotos
A5: 4 | B5: SAT-GES-0004 | C5: cnt-SAT-GES-0004 | D5: Consulta de Estado de Gestión de Agencia Virtual | E5: Estado de Gestión de Agencia Virtual | F5: Herramienta de seguimiento en línea para verificar el estado de aprobación de tu usuario o solicitud en Agencia Virtual. | G5: Consultas y herramientas | H5: Consulta en Base de Datos | I5: Consulta Pública / Buscador | J5: Portal Web SAT | K5: Presencial / Mixto | L5: Solicitantes de Agencia Virtual | M5: Código Tributario, Decreto 6-91 (Arts. 112 y 120) y Acuerdo de Directorio SAT 08-2020. | N5: NO | O5: 1 | P5: contribuyentes | Q5: NO | R5: https://portal.sat.gob.gt/portal/consulta-de-gestion-del-contribuyente/ | S5: FAM-03 Registro Tributario Unificado (RTU) Digital; FAM-05 Solvencias y Convenios de Pago; FAM-09 Agencia Virtual y Servicios Remotos
A6: 5 | B6: SAT-GES-0005 | C6: cnt-SAT-GES-0005 | D6: Solicitud y Emisión de Solvencia Fiscal en Línea | E6: Solvencia Fiscal en Línea | F6: Consulta, pago y descarga del certificado electrónico que acredita la ausencia de adeudos tributarios ante la SAT para fines laborales o personales. | G6: Consultas y herramientas | H6: Trámite / Aplicativo en Línea | I6: Trámite Transaccional | J6: Portal Web SAT | K6: Presencial / Mixto | L6: Personas Individuales | M6: Código Tributario, Decreto 6-91 (Arts. 112 y 120) y Acuerdo de Directorio SAT 08-2020. | N6: NO | O6: 1 | P6: contribuyentes | Q6: NO | R6: https://portal.sat.gob.gt/portal/solvencia-fiscal/ | S6: FAM-03 Registro Tributario Unificado (RTU) Digital; FAM-05 Solvencias y Convenios de Pago
A7: 6 | B7: SAT-GES-0006 | C7: cnt-SAT-GES-0006 | D7: Cita Previa para Gestiones Presenciales | E7: Requisitos para la Atención a través de Cita | F7: Agenda electrónica para programar atención física en agencias tributarias de la SAT en casos especiales que requieran validación presencial. | G7: Operación y declaraciones | H7: Guía Informativa / Texto | I7: Guía de Requisitos y Pasos | J7: Portal Web SAT | K7: Presencial / Mixto | L7: Casos especiales (menores o extranjeros) | M7: Código Tributario, Decreto 6-91 (Arts. 112 y 120) y Acuerdo de Directorio SAT 08-2020. | N7: NO | O7: 1 | P7: contribuyentes | Q7: NO | R7: https://portal.sat.gob.gt/portal/requisitos-tramites-agencias/cita-controlada/ | S7: FAM-03 Registro Tributario Unificado (RTU) Digital; FAM-05 Solvencias y Convenios de Pago
A8: 7 | B8: SAT-GES-0007 | C8: cnt-SAT-GES-0007 | D8: Registrar tu título universitario para ejercer | E8: Registro y Habilitación de Títulos Universitarios | F8: Requisitos, pasos y documentos para registrar y habilitar tu título universitario ante la SAT y pagar los timbres correspondientes. | G8: Operación y declaraciones | H8: Guía Informativa / Texto | I8: Guía de Requisitos y Pasos | J8: Portal Web SAT | K8: Presencial / Mixto | L8: Personas individuales sin actividad económica | M8: Código Tributario, Decreto 6-91 (Arts. 112 y 120) y Acuerdo de Directorio SAT 08-2020. | N8: NO | O8: 1 | P8: contribuyentes | Q8: NO | R8: https://portal.sat.gob.gt/portal/requisitos-tramites-agencias/registro-y-habilitacion-de-titulos-para-ejercer-profesion/ | S8: FAM-03 Registro Tributario Unificado (RTU) Digital
A9: 8 | B9: SAT-GES-0008 | C9: cnt-SAT-GES-0008 | D9: Verificar títulos con código QR | E9: Consulta de Títulos QR | F9: Servicio en línea para verificar la autenticidad y estado de registro de títulos universitarios mediante código QR. | G9: Consultas y herramientas | H9: Guía Informativa / Texto | I9: Guía de Requisitos y Pasos | J9: Portal Web SAT | K9: Presencial / Mixto | L9: NIT sin Obligaciones, Pequeños Contribuyentes, Contribuyente General | M9: Código Tributario, Decreto 6-91 (Arts. 112 y 120) y Acuerdo de Directorio SAT 08-2020. | N9: NO | O9: 1 | P9: contribuyentes | Q9: NO | R9: https://portal.sat.gob.gt/portal/consulta-de-titulos-qr/ | S9: FAM-03 Registro Tributario Unificado (RTU) Digital
A10: 9 | B10: SAT-GES-0009 | C10: cnt-SAT-GES-0009 | D10: Solicitud de acceso a la información pública | E10: Solicitud de Información Pública | F10: Formulario en línea y requisitos para presentar solicitudes de información pública ante la Unidad de Información de la SAT (Decreto 57-2008). | G10: Operación y declaraciones | H10: Guía Informativa / Texto | I10: Guía de Requisitos y Pasos | J10: Portal Web SAT | K10: Presencial / Mixto | L10: Varias categorías de contribuyentes | M10: Código Tributario, Decreto 6-91 (Arts. 112 y 120) y Acuerdo de Directorio SAT 08-2020. | N10: NO | O10: 1 | P10: contribuyentes | Q10: NO | R10: https://portal.sat.gob.gt/portal/solicitud-informacion-publica/ | S10: FAM-03 Registro Tributario Unificado (RTU) Digital
A11: 10 | B11: SAT-GES-0010 | C11: cnt-SAT-GES-0010 | D11: Portal de acceso a la información pública | E11: Acceso a la Información Pública | F11: Publicación de información pública de oficio de la SAT conforme al artículo 10 de la Ley de Acceso a la Información Pública. | G11: Operación y declaraciones | H11: Guía Informativa / Texto | I11: Guía de Requisitos y Pasos | J11: Portal Web SAT | K11: Presencial / Mixto | L11: NIT sin Obligaciones, Pequeños Contribuyentes, Contribuyente General, Contribuyentes Especiales | M11: Código Tributario, Decreto 6-91 (Arts. 112 y 120) y Acuerdo de Directorio SAT 08-2020. | N11: NO | O11: 1 | P11: contribuyentes | Q11: NO | R11: https://portal.sat.gob.gt/portal/libre-acceso-la-informacion-publica/ | S11: FAM-03 Registro Tributario Unificado (RTU) Digital
A12: 11 | B12: SAT-GES-0011 | C12: cnt-SAT-GES-0011 | D12: Solicitar tu NIT en línea | E12: Solicitud Electrónica de NIT | F12: Requisitos, pasos y documentos para solicitar tu Número de Identificación Tributaria (NIT) en línea. | G12: Modificaciones y cierre | H12: Guía Informativa / Texto | I12: Guía de Requisitos y Pasos | J12: Portal Web SAT | K12: Presencial / Mixto | L12: Personas y empresas del régimen de pequeño contribuyente | M12: Decreto 27-92 (Ley del IVA, Arts. 45 al 50) y Decreto 7-2019 (Ley de Simplificación Tributaria). | N12: NO | O12: 1 | P12: contribuyentes | Q12: NO | R12: https://portal.sat.gob.gt/portal/solicitud-electronica-de-nit/ | S12: FAM-03 Registro Tributario Unificado (RTU) Digital
A13: 12 | B13: SAT-GES-0012 | C13: cnt-SAT-GES-0012 | D13: Inscribirte como productor agropecuario, artesanal o de reciclaje | E13: Inscripción en el Registro de Productores de productos Agropecuarios, Artesanales y Reciclados | F13: Requisitos, pasos y documentos para inscribirte como productor agropecuario, artesanal o de reciclaje. | G13: Modificaciones y cierre | H13: Guía Informativa / Texto | I13: Guía de Requisitos y Pasos | J13: Portal Web SAT | K13: Presencial / Mixto | L13: Personas y empresas del régimen de pequeño contribuyente | M13: Decreto 27-92 (Ley del IVA, Arts. 45 al 50) y Decreto 7-2019 (Ley de Simplificación Tributaria). | N13: NO | O13: 1 | P13: contribuyentes | Q13: NO | R13: https://portal.sat.gob.gt/portal/requisitos-tramites-agencia-virtual/inscripcion-en-el-registro-de-productores-de-productos-agropecuarios-artesanales-y-reciclados/ | S13: FAM-03 Registro Tributario Unificado (RTU) Digital
... A425: 424 | B425: SAT-GES-0424 | C425: cnt-SAT-GES-0424 | D425: Curso Virtual: Generalidades de la Declaración Única Centroamericana (DUCA) | E425: Curso: generalidades de la DUCA | F425: Capacitación oficial interactiva sobre llenado, transmisión y soporte legal de la DUCA (modalidades D, F y T) para el despacho de mercancías. | G425: Normativa y asistencia | H425: Trámite / Aplicativo en Línea | I425: Trámite / Aplicativo en Línea | J425: Portal Web SAT | K425: Digital / Web | L425: Agentes de Aduana, Importadores y Exportadores | M425: CAUCA IV (Arts. 22 al 28), RECAUCA IV (Auxiliares de la Función Pública) y Ley Nacional de Aduanas. | N425: NO | O425: 1 | P425: comercio_exterior | Q425: NO | R425: https://sites.google.com/capacitacionessat.page/cultura-tributariad/cursos-virtuales-sat/aduanas/declaraci%C3%B3n-%C3%BAnica-centroamericana-duca | S425: FAM-03 Registro Tributario Unificado (RTU) Digital; FAM-04 Declaraciones Aduaneras (DUCAs); FAM-08 Auxiliares de la Función Pública Aduanera (AFPA)
A426: 425 | B426: SAT-GES-0425 | C426: cnt-SAT-GES-0425 | D426: Consultas de aduanas (Rampa de revisión, selectivo y estados) | E426: Consultas de aduanas (Rampa de revisión, revisores, retención/liberación, arancel) | F426: Consultar en tiempo real el estatus de rampa de revisión, revisores asignados, retención y levante de mercancías para despachos aduaneros. | G426: Consultas y herramientas | H426: Consulta a Base de Datos | I426: Consulta Pública / Buscador | J426: Portal Web SAT | K426: 100% Digital | M426: CAUCA IV y RECAUCA IV (Arts. 86 al 90, Apoderados Especiales Aduaneros). | N426: NO | O426: 1 | P426: comercio_exterior | Q426: NO | R426: https://portal.sat.gob.gt/portal/consultas-aduanas/ | S426: FAM-04 Declaraciones Aduaneras (DUCAs); FAM-08 Auxiliares de la Función Pública Aduanera (AFPA)
A427: 426 | B427: SAT-GES-0426 | C427: cnt-SAT-GES-0426-ZDEEP-USR | D427: Requisitos para consulta de expedientes de gestión aduanera | E427: Requisitos para consulta de expedientes de gestión aduanera | F427: Gestión y especificaciones para Requisitos para consulta de expedientes de gestión aduanera conforme a normativa aduanera aplicable. | G427: Consultas y herramientas | H427: Consulta a Base de Datos | I427: Consulta Pública / Buscador | J427: Portal Web SAT | K427: 100% Digital | M427: Decreto 22-73 (Ley Orgánica de ZOLIC / ZDEEP), CAUCA IV y RECAUCA IV. | N427: SÍ | O427: 5 | P427: comercio_exterior | Q427: NO | R427: https://portal.sat.gob.gt/portal/requisitos-de-aduanas/#1542142398181-8db4844a-6760 | S427: FAM-04 Declaraciones Aduaneras (DUCAs); FAM-07 Zonas de Desarrollo Económico Especial Público (ZDEEP)
A428: 427 | B428: SAT-GES-0427 | C428: cnt-SAT-GES-0427 | D428: Unión aduanera (Procedimientos y resoluciones de facilitación) | E428: Unión aduanera (Procedimientos y resoluciones) | F428: Consultar resoluciones, directrices operativas y procedimientos de paso ágil en puestos fronterizos integrados de la Unión Aduanera. | G428: Consultas y herramientas | H428: Guía Informativa / Texto | I428: Guía de Requisitos y Pasos | J428: Portal Web SAT | K428: 100% Digital | M428: CAUCA IV y RECAUCA IV (Arts. 86 al 90, Apoderados Especiales Aduaneros). | N428: NO | O428: 1 | P428: comercio_exterior | Q428: NO | R428: https://portal.sat.gob.gt/portal/union-aduanera/ | S428: FAM-04 Declaraciones Aduaneras (DUCAs); FAM-08 Auxiliares de la Función Pública Aduanera (AFPA)
A429: 428 | B429: SAT-GES-0428 | C429: cnt-SAT-GES-0428 | D429: Capacitaciones para auxiliares de la función pública | E429: Capacitaciones para auxiliares de la función pública | F429: Inscripción y acceso a programas de capacitación técnica oficial sobre procedimientos aduaneros para auxiliares y apoderados. | G429: Normativa y asistencia | H429: Trámite / Aplicativo en Línea | I429: Multimedia / Video e Infografía | J429: Portal Web SAT | K429: 100% Digital | M429: CAUCA IV y RECAUCA IV (Arts. 86 al 90, Apoderados Especiales Aduaneros). | N429: SÍ | O429: 3 | P429: comercio_exterior | Q429: NO | R429: https://portal.sat.gob.gt/portal/#capacitacion | S429: FAM-03 Registro Tributario Unificado (RTU) Digital; FAM-04 Declaraciones Aduaneras (DUCAs); FAM-08 Auxiliares de la Función Pública Aduanera (AFPA)
A430: 429 | B430: SAT-GES-0429 | C430: cnt-SAT-GES-0429 | D430: Legislación aduanera (Biblioteca en línea, CAUCA y RECAUCA) | E430: Legislación aduanera (Biblioteca en línea SAT) | F430: Compendio digital de leyes, reglamentos (CAUCA, RECAUCA, Ley de Aduanas) y resoluciones administrativas aplicables a apoderados especiales. | G430: Normativa y asistencia | H430: Guía Informativa / Texto | I430: Guía de Requisitos y Pasos | J430: Portal Web SAT | K430: 100% Digital | M430: CAUCA IV y RECAUCA IV (Arts. 86 al 90, Apoderados Especiales Aduaneros). | N430: NO | O430: 1 | P430: comercio_exterior | Q430: NO | R430: https://portal.sat.gob.gt/portal/biblioteca-en-linea-sat/legislacion-aduanera/ | S430: FAM-04 Declaraciones Aduaneras (DUCAs); FAM-08 Auxiliares de la Función Pública Aduanera (AFPA)
A431: 430 | B431: SAT-GES-0430 | C431: cnt-SAT-GES-0430-DAT | D431: Preguntas frecuentes sobre temas aduaneros | E431: Preguntas frecuentes sobre temas aduaneros | F431: Respuestas a consultas frecuentes sobre manejo de carga, plazos de permanencia temporal y levante de mercancías en recintos. | G431: Normativa y asistencia | H431: Guía Informativa / Texto | I431: Normativa y Criterio Legal | J431: Portal Web SAT | K431: 100% Digital | M431: CAUCA IV y RECAUCA IV (Depósitos Aduaneros Temporales en puertos y aeropuertos). | N431: SÍ | O431: 4 | P431: comercio_exterior | Q431: NO | R431: https://portal.sat.gob.gt/portal/preguntas-frecuentes/temas-aduaneros/ | S431: FAM-04 Declaraciones Aduaneras (DUCAs); FAM-08 Auxiliares de la Función Pública Aduanera (AFPA)
A432: 431 | B432: SAT-GES-0431 | C432: cnt-SAT-GES-0431-ZDEEP-USR | D432: Procedimientos administrativos de aduanas (Sanciones y recursos) | E432: Procedimientos administrativos de aduanas (Sanciones y recursos) | F432: Gestión y especificaciones para Procedimientos administrativos de aduanas (Sanciones y recursos) conforme a normativa aduanera aplicable. | G432: Normativa y asistencia | H432: Trámite / Aplicativo en Línea | I432: Multimedia / Video e Infografía | J432: Portal Web SAT | K432: 100% Digital | M432: Decreto 22-73 (Ley Orgánica de ZOLIC / ZDEEP), CAUCA IV y RECAUCA IV. | N432: SÍ | O432: 5 | P432: comercio_exterior | Q432: NO | R432: https://portal.sat.gob.gt/portal/procedimientos-aduanas/#1570112033454-be3581a4-383a | S432: FAM-04 Declaraciones Aduaneras (DUCAs); FAM-07 Zonas de Desarrollo Económico Especial Público (ZDEEP)
A433: 432 | B433: SAT-GES-0432 | C433: cnt-SAT-GES-0432 | D433: Procedimientos, instructivos, manuales y guías para gestiones aduaneras | E433: Procedimientos, instructivos, manuales y guías para gestiones aduaneras | F433: Manuales operativos y guías técnicas para el despacho de mercancías, llenado de formatos y gestión de apoderados. | G433: Normativa y asistencia | H433: Guía Informativa / Texto | I433: Guía de Requisitos y Pasos | J433: Portal Web SAT | K433: 100% Digital | M433: CAUCA IV y RECAUCA IV (Arts. 86 al 90, Apoderados Especiales Aduaneros). | N433: NO | O433: 1 | P433: comercio_exterior | Q433: NO | R433: https://portal.sat.gob.gt/portal/procedimientos-aduanas/#1571412473853-2ed0b43f-287f | S433: FAM-04 Declaraciones Aduaneras (DUCAs); FAM-08 Auxiliares de la Función Pública Aduanera (AFPA)
A434: 433 | B434: SAT-GES-0433 | C434: cnt-SAT-GES-0433 | D434: Declaración anticipada | E434: Declaración anticipada | F434: Transmitir y registrar la declaración aduanera antes del arribo del medio de transporte para agilizar el despacho y levante de mercancías. | G434: Operación y declaraciones | H434: Guía Informativa / Texto | I434: Guía de Requisitos y Pasos | J434: Portal Web SAT | K434: 100% Digital | M434: CAUCA IV y RECAUCA IV (Arts. 86 al 90, Apoderados Especiales Aduaneros). | N434: NO | O434: 1 | P434: comercio_exterior | Q434: NO | R434: https://portal.sat.gob.gt/portal/facilitacion-de-comercio/#1559325573466-1284efd5-2d1b | S434: FAM-04 Declaraciones Aduaneras (DUCAs); FAM-08 Auxiliares de la Función Pública Aduanera (AFPA)
A435: 434 | B435: SAT-GES-0434 | C435: cnt-SAT-GES-0434 | D435: Declaración de mercancías (DUCA y Aduana sin papeles) | E435: Declaración de mercancías (DUCA y Aduana sin papeles) | F435: Directrices técnicas y soporte normativo para la elaboración, firma electrónica y transmisión de la Declaración Única Centroamericana (DUCA). | G435: Operación y declaraciones | H435: Trámite / Aplicativo en Línea | I435: Trámite Transaccional | J435: Portal Web SAT | K435: 100% Digital | M435: CAUCA IV y RECAUCA IV (Arts. 86 al 90, Apoderados Especiales Aduaneros). | N435: SÍ | O435: 3 | P435: comercio_exterior | Q435: NO | R435: https://portal.sat.gob.gt/portal/procedimientos-aduanas/#1555105635499-a4507e58-10e9 | S435: FAM-04 Declaraciones Aduaneras (DUCAs); FAM-08 Auxiliares de la Función Pública Aduanera (AFPA)
A436: 435 | B436: SAT-GES-0435 | C436: cnt-SAT-GES-0435 | D436: Sistema de franquicias electrónicas | E436: Sistema de franquicias electrónicas | F436: Plataforma web para gestionar, registrar y consultar la aplicación de franquicias y exenciones arancelarias autorizadas. | G436: Operación y declaraciones | H436: Trámite / Aplicativo en Línea | I436: Trámite Transaccional | J436: Portal Web SAT | K436: 100% Digital | M436: CAUCA IV y RECAUCA IV (Arts. 86 al 90, Apoderados Especiales Aduaneros). | N436: NO | O436: 1 | P436: comercio_exterior | Q436: NO | R436: https://portal.sat.gob.gt/portal/franquicias-electronicas/ | S436: FAM-04 Declaraciones Aduaneras (DUCAs); FAM-08 Auxiliares de la Función Pública Aduanera (AFPA); FAM-10 Franquicias y Exenciones Tributarias
A437: 436 | B437: SAT-GES-0436 | C437: cnt-SAT-GES-0436 | D437: Autorización inicial y registro de mandato para apoderados especiales | E437: [Propuesta brecha] Autorización inicial y registro de mandato de apoderado especial | F437: Procedimiento normativo propuesto para registrar mandatos especiales aduaneros, habilitar firma autorizada y emitir acreditación ante SAT. | G437: Empezar y registrarse | H437: Guía Informativa / Texto | I437: Guía de Requisitos y Pasos | J437: Portal Web SAT | K437: 100% Digital | M437: CAUCA IV y RECAUCA IV (Arts. 86 al 90, Apoderados Especiales Aduaneros). | N437: NO | O437: 1 | P437: comercio_exterior | Q437: SÍ | R437: https://portal.sat.gob.gt/portal/requisitos-de-aduanas/ | S437: FAM-04 Declaraciones Aduaneras (DUCAs); FAM-08 Auxiliares de la Función Pública Aduanera (AFPA)
... A450: 449 | B450: SAT-GES-0449 | C450: cnt-SAT-GES-0449-AGD | D450: Solvencia fiscal (Requisito indispensable de renovación como auxiliar aduanero AFPA) | E450: Solvencia fiscal (Requisito indispensable de renovación como auxiliar aduanero AFPA) | F450: Obtención en línea de la solvencia fiscal requerida para la prórroga y continuidad de la habilitación operativa ante la SAT. | G450: Empezar y registrarse | H450: Guía Informativa / Texto | I450: Guía de Requisitos y Pasos | J450: Portal Web SAT | K450: 100% Digital | M450: Decreto 1236 (Ley de Almacenes Generales de Depósito) y RECAUCA IV Art. 119. | N450: NO | O450: 1 | P450: comercio_exterior | Q450: NO | R450: https://portal.sat.gob.gt/portal/solvencia-fiscal/ | S450: FAM-04 Declaraciones Aduaneras (DUCAs); FAM-05 Solvencias y Convenios de Pago; FAM-08 Auxiliares de la Función Pública Aduanera (AFPA)
A451: 450 | B451: SAT-GES-0450 | C451: cnt-SAT-GES-0450 | D451: Declaración de Abandono y Subasta Aduanera de Mercancías | E451: Procedimiento de Declaración de Abandono y Notificación de Subasta Aduanera | F451: Procedimiento normado para emitir el acta de abandono tácito tras vencer el plazo legal de permanencia y trasladar el expediente a la SAT para subasta pública o destrucción. | G451: Modificaciones y cierre | H451: Guía Informativa / Texto | I451: Guía Informativa / Texto | J451: Portal Web SAT | K451: Digital / Web | L451: Depositarios Aduaneros y Almacenes Fiscales | M451: Código Aduanero Uniforme Centroamericano (CAUCA IV) y su Reglamento (RECAUCA IV). | N451: NO | O451: 1 | P451: comercio_exterior | Q451: NO | R451: https://portal.sat.gob.gt/portal/subastas-y-donaciones-aduaneras/ | S451: FAM-04 Declaraciones Aduaneras (DUCAs); FAM-08 Auxiliares de la Función Pública Aduanera (AFPA)
A452: 451 | B452: SAT-GES-0451 | C452: cnt-SAT-GES-0451 | D452: Sistema de Cobro por Permanencia de Mercancías (SCP) | E452: Cobro por permanencia de mercancías | F452: Aplicativo web oficial para consultar y liquidar las tarifas por días de permanencia de mercancías bajo control aduanero en almacén fiscal antes del levante. | G452: Operación y declaraciones | H452: Trámite / Aplicativo en Línea | I452: Trámite / Aplicativo en Línea | J452: Portal Web SAT | K452: Digital / Web | L452: Depositarios Aduaneros, Almacenes Fiscales y Agentes de Aduana | M452: CAUCA IV y RECAUCA IV (Arts. 119 al 129, Régimen de Depósito Aduanero o Fiscal). | N452: NO | O452: 1 | P452: comercio_exterior | Q452: NO | R452: https://portal.sat.gob.gt/portal/sistema-de-cobro-por-permanencia/ | S452: FAM-04 Declaraciones Aduaneras (DUCAs); FAM-08 Auxiliares de la Función Pública Aduanera (AFPA)
A453: 452 | B453: SAT-GES-0452 | C453: cnt-SAT-GES-0452-DAT | D453: Consultas de aduanas (Asignación a rampa de revisión, revisores, retención y liberación) | E453: Consultas de aduanas (Asignación a rampa de revisión, revisores, retención y liberación) | F453: Consulta en línea de asignación a rampa de revisión física, técnicos asignados, retenciones y órdenes de levante de mercancías. | G453: Consultas y herramientas | H453: Consulta a Base de Datos | I453: Consulta Pública / Buscador | J453: Portal Web SAT | K453: 100% Digital | M453: CAUCA IV y RECAUCA IV (Depósitos Aduaneros Temporales en puertos y aeropuertos). | N453: NO | O453: 1 | P453: comercio_exterior | Q453: NO | R453: https://portal.sat.gob.gt/portal/consultas-aduanas/ | S453: FAM-04 Declaraciones Aduaneras (DUCAs); FAM-08 Auxiliares de la Función Pública Aduanera (AFPA)
A454: 453 | B454: SAT-GES-0453 | C454: cnt-SAT-GES-0453-DAT | D454: Control de descarga, ingreso de bultos y actas de recepción DAT | E454: [Propuesta brecha] Control de descarga, ingreso de bultos y actas de recepción DAT | F454: Procedimiento propuesto para registrar digitalmente actas de recepción, inconsistencias y control de descarga de bultos en recintos DAT. | G454: Operación y declaraciones | H454: Descarga / Software | I454: Recurso / Software Descargable | J454: Portal Web SAT | K454: 100% Digital | M454: CAUCA IV y RECAUCA IV (Depósitos Aduaneros Temporales en puertos y aeropuertos). | N454: NO | O454: 1 | P454: comercio_exterior | Q454: SÍ | R454: https://portal.sat.gob.gt/portal/procedimientos-aduanas/ | S454: FAM-04 Declaraciones Aduaneras (DUCAs); FAM-08 Auxiliares de la Función Pública Aduanera (AFPA)
A455: 454 | B455: SAT-GES-0454 | C455: cnt-SAT-GES-0454-DAT | D455: Legislación aduanera (RECAUCA Art. 119 - Disposiciones sobre depósitos) | E455: Legislación aduanera (RECAUCA Art. 119 - Disposiciones sobre depósitos) | F455: Marco normativo del CAUCA y RECAUCA (Art. 119) sobre operación, obligaciones y plazos legales en depósitos temporales. | G455: Normativa y asistencia | H455: Guía Informativa / Texto | I455: Normativa y Criterio Legal | J455: Portal Web SAT | K455: 100% Digital | M455: CAUCA IV y RECAUCA IV (Depósitos Aduaneros Temporales en puertos y aeropuertos). | N455: NO | O455: 1 | P455: comercio_exterior | Q455: NO | R455: https://portal.sat.gob.gt/portal/biblioteca-en-linea-sat/legislacion-aduanera/ | S455: FAM-04 Declaraciones Aduaneras (DUCAs); FAM-08 Auxiliares de la Función Pública Aduanera (AFPA)
A456: 455 | B456: SAT-GES-0455 | C456: cnt-SAT-GES-0455-DAT | D456: Monitoreo de sistemas informáticos de aduanas | E456: Monitoreo de sistemas informáticos de aduanas | F456: Monitoreo de disponibilidad y operatividad en tiempo real de los sistemas informáticos aduaneros para recintos temporales. | G456: Consultas y herramientas | H456: Consulta a Base de Datos | I456: Consulta Pública / Buscador | J456: Portal Web SAT | K456: 100% Digital | M456: CAUCA IV y RECAUCA IV (Depósitos Aduaneros Temporales en puertos y aeropuertos). | N456: SÍ | O456: 2 | P456: comercio_exterior | Q456: NO | R456: https://portal.sat.gob.gt/portal/consultas-aduanas/ | S456: FAM-03 Registro Tributario Unificado (RTU) Digital; FAM-04 Declaraciones Aduaneras (DUCAs); FAM-08 Auxiliares de la Función Pública Aduanera (AFPA)
A457: 456 | B457: SAT-GES-0456 | C457: cnt-SAT-GES-0456-DAT | D457: Registro de admisión temporal de contenedores terrestres y su ampliación | E457: Registro de admisión temporal de contenedores terrestres y su ampliación | F457: Control y registro de ingreso y ampliación de plazo para la admisión temporal de contenedores y chasises terrestres. | G457: Operación y declaraciones | H457: Guía Informativa / Texto | I457: Guía de Requisitos y Pasos | J457: Portal Web SAT | K457: 100% Digital | M457: CAUCA IV y RECAUCA IV (Depósitos Aduaneros Temporales en puertos y aeropuertos). | N457: NO | O457: 1 | P457: comercio_exterior | Q457: NO | R457: https://portal.sat.gob.gt/portal/consultas-aduanas/ | S457: FAM-04 Declaraciones Aduaneras (DUCAs); FAM-08 Auxiliares de la Función Pública Aduanera (AFPA)
A458: 457 | B458: SAT-GES-0457 | C458: cnt-SAT-GES-0457-DAT | D458: Requisitos para habilitación y delimitación de recintos aduaneros temporales (DAT) | E458: [Propuesta brecha] Requisitos para habilitación y delimitación de recintos aduaneros temporales (DAT) | F458: Requisitos normativos propuestos para delimitar perímetros, equipamiento y habilitación inicial de recintos aduaneros temporales. | G458: Empezar y registrarse | H458: Guía Informativa / Texto | I458: Guía de Requisitos y Pasos | J458: Portal Web SAT | K458: 100% Digital | M458: CAUCA IV y RECAUCA IV (Depósitos Aduaneros Temporales en puertos y aeropuertos). | N458: NO | O458: 1 | P458: comercio_exterior | Q458: SÍ | R458: https://portal.sat.gob.gt/portal/requisitos-de-aduanas/ | S458: FAM-04 Declaraciones Aduaneras (DUCAs); FAM-08 Auxiliares de la Función Pública Aduanera (AFPA)
A459: 458 | B459: SAT-GES-0458 | C459: cnt-SAT-GES-0458-DAT | D459: Sistema de cobro por permanencia en el país | E459: Sistema de cobro por permanencia en el país | F459: Plataforma para calcular y gestionar el cobro por días de permanencia de contenedores y medios de transporte en el país. | G459: Consultas y herramientas | H459: Trámite / Aplicativo en Línea | I459: Trámite Transaccional | J459: Portal Web SAT | K459: 100% Digital | M459: CAUCA IV y RECAUCA IV (Arts. 119 al 129, Régimen de Depósito Aduanero o Fiscal). | N459: NO | O459: 1 | P459: comercio_exterior | Q459: NO | R459: https://portal.sat.gob.gt/portal/consultas-aduanas/ | S459: FAM-04 Declaraciones Aduaneras (DUCAs); FAM-08 Auxiliares de la Función Pública Aduanera (AFPA)
A460: 459 | B460: SAT-GES-0459 | C460: cnt-SAT-GES-0459 | D460: Guía y Despacho Simplificado para Importación Courier | E460: Conceptos generales de importación | F460: Procedimiento para la clasificación, aforo y desaduanamiento expedito de envíos de entrega rápida en terminales de carga aérea. | G460: Operación y declaraciones | H460: Guía Informativa / Texto | I460: Guía Informativa / Texto | J460: Portal Web SAT | K460: Digital / Web | L460: Empresas Courier y Consolidadores de Paquetería | M460: CAUCA IV y RECAUCA IV (Arts. 574 al 596, Régimen de Envíos de Entrega Rápida o Courier). | N460: NO | O460: 1 | P460: comercio_exterior | Q460: NO | R460: https://portal.sat.gob.gt/portal/programa-miad/componente-procesos-2/importacion/ | S460: FAM-04 Declaraciones Aduaneras (DUCAs); FAM-08 Auxiliares de la Función Pública Aduanera (AFPA)
A461: 460 | B461: SAT-GES-0460 | C461: cnt-SAT-GES-0460 | D461: Sistema de Franquicias Electrónicas Aduaneras | E461: Sistema de franquicias electrónicas | F461: Aplicativo web para gestionar el beneficio arancelario de franquicias para encomiendas no comerciales y envíos diplomáticos. | G461: Operación y declaraciones | H461: Trámite / Aplicativo en Línea | I461: Trámite / Aplicativo en Línea | J461: Portal Web SAT | K461: Digital / Web | L461: Empresas Courier, Diplomáticos y Beneficiarios de Exención | M461: CAUCA IV y RECAUCA IV (Arts. 574 al 596, Régimen de Envíos de Entrega Rápida o Courier). | N461: NO | O461: 1 | P461: comercio_exterior | Q461: NO | R461: https://portal.sat.gob.gt/portal/franquicias-electronicas/ | S461: FAM-04 Declaraciones Aduaneras (DUCAs); FAM-08 Auxiliares de la Función Pública Aduanera (AFPA); FAM-10 Franquicias y Exenciones Tributarias
A462: 461 | B462: SAT-GES-0461 | C462: cnt-SAT-GES-0461 | D462: Registro y Recepción de Póliza de Fianza / Seguro de Caución Courier | E462: Entregar seguro de caución para importación | F462: Recepción y validación de la fianza de operación anual exigida por el Art. 576 del RECAUCA para garantizar obligaciones aduaneras. | G462: Empezar y registrarse | H462: Trámite / Aplicativo en Línea | I462: Trámite / Aplicativo en Línea | J462: Portal Web SAT | K462: Digital / Web | L462: Empresas de Entrega Rápida o Courier | M462: CAUCA IV y RECAUCA IV (Arts. 574 al 596, Régimen de Envíos de Entrega Rápida o Courier). | N462: NO | O462: 1 | P462: comercio_exterior | Q462: NO | R462: https://portal.sat.gob.gt/portal/requisitos-tramites-agencias/recepcion-de-seguro-de-caucion-importacion-y-admision-temporal/ | S462: FAM-04 Declaraciones Aduaneras (DUCAs); FAM-08 Auxiliares de la Función Pública Aduanera (AFPA)
A463: 462 | B463: SAT-GES-0462 | C463: cnt-SAT-GES-0462 | D463: Autorización de Cartas de Ingreso a Zona Primaria Aduanera | E463: Autorizar cartas de ingreso a zona primaria | F463: Procedimiento y requisitos para autorizar el ingreso temporal de unidades de transporte de carga y conductores a áreas primarias portuarias y terrestres. | G463: Operación y declaraciones | H463: Guía Informativa / Texto | I463: Guía Informativa / Texto | J463: Portal Web SAT | K463: Digital / Web | L463: Transportistas Terrestres, Navieros y Agentes de Carga | M463: CAUCA IV (Arts. 18 al 28), RECAUCA IV (Tránsito Aduanero Internacional Terrestre) y Ley de Aduanas. | N463: NO | O463: 1 | P463: comercio_exterior | Q463: NO | R463: https://portal.sat.gob.gt/portal/requisitos-tramites-aduanas/autorizacion-de-cartas-de-ingreso-a-zona-primaria/ | S463: FAM-03 Registro Tributario Unificado (RTU) Digital; FAM-04 Declaraciones Aduaneras (DUCAs); FAM-08 Auxiliares de la Función Pública Aduanera (AFPA)
...

Sheet Contenidos Transversales (17)
A1: No. | B1: Código Oficial | C1: Nombre del Contenido Canónico | D1: Apariciones | E1: Segmentos que lo Comparten | F1: Ubicaciones / Nodos en el Árbol de Navegación | G1: ¿Para qué sirve? | H1: URL Portal SAT
A2: 1 | B2: SAT-GES-0024 | C2: Curso: Régimen Electrónico de Pequeño Contribuyente | D2: 2 | E2: contribuyentes | F2: • > > • > > | G2: Capacitación virtual de la SAT sobre Régimen Electrónico de Pequeño Contribuyente. | H2: https://sites.google.com/capacitacionessat.page/cultura-tributariad/cursos-virtuales-sat/impuesto-al-valor-agregado-iva/r%C3%A9gimen-electr%C3%B3nico-de-peque%C3%B1o-contribuyente
A3: 2 | B3: SAT-GES-0092 | C3: Presentaciones virtuales | D3: 2 | E3: contribuyentes | F3: • > > • > > | G3: Descargar diapositivas y presentaciones oficiales utilizadas en las jornadas de capacitación tributaria de la SAT. | H3: https://portal.sat.gob.gt/portal/referencia-virtual/
A4: 3 | B4: SAT-GES-0159 | C4: Curso: rentas y ganancias de capital | D4: 2 | E4: contribuyentes | F4: • > > • > > | G4: Capacitación virtual de la SAT sobre rentas y ganancias de capital. | H4: https://sites.google.com/capacitacionessat.page/cultura-tributariad/cursos-virtuales-sat/impuesto-sobre-la-renta/rentas-de-capital-ganancias-y-p%C3%A9rdidas-de-capital
A5: 4 | B5: SAT-GES-0230 | C5: Devolución del impuesto de herencias, legados y donaciones | D5: 2 | E5: contribuyentes | F5: • > > • > > | G5: Tramitar la restitución de pagos indebidos practicados sobre el Impuesto sobre Herencias, Legados y Donaciones. | H5: https://portal.sat.gob.gt/portal/requisitos-tramites-agencias/devoulucion-impuesto-de-herencias-legados-y-donaciones/
A6: 5 | B6: SAT-GES-0340 | C6: Servicio en línea para consultar listado de contribuyentes morosos. | D6: 2 | E6: comercio_exterior, contribuyentes | F6: • > > • > > | G6: Consultar el listado oficial de contribuyentes en situación de morosidad tributaria publicado en cumplimiento del Código Tributario. | H6: https://portal.sat.gob.gt/portal/listado-de-contribuyentes-morosos/
A7: 6 | B7: SAT-GES-0426 | C7: Requisitos para consulta de expedientes de gestión aduanera | D7: 5 | E7: comercio_exterior | F7: • > > • > > • > > • > > • > > | G7: Gestión y especificaciones para Requisitos para consulta de expedientes de gestión aduanera conforme a normativa aduanera aplicable. | H7: https://portal.sat.gob.gt/portal/requisitos-de-aduanas/#1542142398181-8db4844a-6760
A8: 7 | B8: SAT-GES-0428 | C8: Capacitaciones para auxiliares de la función pública | D8: 3 | E8: comercio_exterior | F8: • > > • > > • > > | G8: Inscripción y acceso a programas de capacitación técnica oficial sobre procedimientos aduaneros para auxiliares y apoderados. | H8: https://portal.sat.gob.gt/portal/#capacitacion
A9: 8 | B9: SAT-GES-0430 | C9: Preguntas frecuentes sobre temas aduaneros | D9: 4 | E9: comercio_exterior | F9: • > > • > > • > > • > > | G9: Respuestas a consultas frecuentes sobre manejo de carga, plazos de permanencia temporal y levante de mercancías en recintos. | H9: https://portal.sat.gob.gt/portal/preguntas-frecuentes/temas-aduaneros/
A10: 9 | B10: SAT-GES-0431 | C10: Procedimientos administrativos de aduanas (Sanciones y recursos) | D10: 5 | E10: comercio_exterior | F10: • > > • > > • > > • > > • > > | G10: Gestión y especificaciones para Procedimientos administrativos de aduanas (Sanciones y recursos) conforme a normativa aduanera aplicable. | H10: https://portal.sat.gob.gt/portal/procedimientos-aduanas/#1570112033454-be3581a4-383a
A11: 10 | B11: SAT-GES-0434 | C11: Declaración de mercancías (DUCA y Aduana sin papeles) | D11: 3 | E11: comercio_exterior | F11: • > > • > > • > > | G11: Directrices técnicas y soporte normativo para la elaboración, firma electrónica y transmisión de la Declaración Única Centroamericana (DUCA). | H11: https://portal.sat.gob.gt/portal/procedimientos-aduanas/#1555105635499-a4507e58-10e9
A12: 11 | B12: SAT-GES-0437 | C12: Auxiliares de la función pública aduanera (Carné, componente ActiveX PKI/DUA) | D12: 3 | E12: comercio_exterior | F12: • > > • > > • > > | G12: Directrices para la obtención del carné de identificación oficial y soporte para la instalación de firma digital ActiveX PKI para DUCA. | H12: https://portal.sat.gob.gt/portal/procedimientos-aduanas/#1570112086149-de895ac7-a87c
A13: 12 | B13: SAT-GES-0439 | C13: Requisitos para la renovación de operación de auxiliares de la función pública | D13: 3 | E13: comercio_exterior | F13: • > > • > > • > > | G13: Requisitos y gestión de prórroga anual de autorización y actualización de fianza para operar como apoderado especial aduanero. | H13: https://portal.sat.gob.gt/portal/requisitos-de-aduanas/#1608063945646-f9ebd644-65ff
... A18: 17 | B18: SAT-GES-0455 | C18: Monitoreo de sistemas informáticos de aduanas | D18: 2 | E18: comercio_exterior | F18: • > > • > > | G18: Monitoreo de disponibilidad y operatividad en tiempo real de los sistemas informáticos aduaneros para recintos temporales. | H18: https://portal.sat.gob.gt/portal/consultas-aduanas/

Sheet Mapeo a Nodos (715)
A1: No. | B1: Código Oficial (SAT-GES-####) | C1: ID Nodo de Navegación | D1: Nombre de la Gestión / Contenido | E1: Segmento (Nivel 1) | F1: Categoría (Nivel 2) | G1: Subcategoría (Nivel 3) | H1: Tema / Subárea (Nivel 4) | I1: Ruta de Navegación (Miga de Pan) | J1: Etapa del Ciclo de Vida | K1: Tipo de Interacción | L1: URL Portal SAT
A2: 1 | B2: SAT-GES-0001 | C2: SAT-GES-0001 | D2: Solicitar Número de Identificación Tributaria (NIT) | H2: — | J2: Empezar y registrarse | K2: Guía Informativa / Texto | L2: https://portal.sat.gob.gt/portal/requisitos-de-personas-empresas/#1615485066841-639e67c5-51e3
A3: 2 | B3: SAT-GES-0002 | C3: SAT-GES-0002 | D3: Actualización de Datos y Transición de Régimen | H3: — | J3: Modificaciones y cierre | K3: Guía Informativa / Texto | L3: https://portal.sat.gob.gt/portal/requisitos-de-personas-empresas/#1541621044169-4198d06d-693f
A4: 3 | B4: SAT-GES-0003 | C4: SAT-GES-0003 | D4: Solicitud y Activación de Agencia Virtual | H4: — | J4: Operación y declaraciones | K4: Trámite / Aplicativo en Línea | L4: https://farm3.sat.gob.gt/menu/login.jsf
A5: 4 | B5: SAT-GES-0004 | C5: SAT-GES-0004 | D5: Consulta de Estado de Gestión de Agencia Virtual | H5: — | J5: Consultas y herramientas | K5: Consulta en Base de Datos | L5: https://portal.sat.gob.gt/portal/consulta-de-gestion-del-contribuyente/
A6: 5 | B6: SAT-GES-0005 | C6: SAT-GES-0005 | D6: Solicitud y Emisión de Solvencia Fiscal en Línea | H6: — | J6: Consultas y herramientas | K6: Trámite / Aplicativo en Línea | L6: https://portal.sat.gob.gt/portal/solvencia-fiscal/
A7: 6 | B7: SAT-GES-0006 | C7: SAT-GES-0006 | D7: Cita Previa para Gestiones Presenciales | H7: — | J7: Operación y declaraciones | K7: Guía Informativa / Texto | L7: https://portal.sat.gob.gt/portal/requisitos-tramites-agencias/cita-controlada/
A8: 7 | B8: SAT-GES-0007 | C8: SAT-GES-0007 | D8: Registrar tu título universitario para ejercer | H8: — | J8: Operación y declaraciones | K8: Guía Informativa / Texto | L8: https://portal.sat.gob.gt/portal/requisitos-tramites-agencias/registro-y-habilitacion-de-titulos-para-ejercer-profesion/
A9: 8 | B9: SAT-GES-0008 | C9: SAT-GES-0008 | D9: Verificar títulos con código QR | H9: — | J9: Consultas y herramientas | K9: Guía Informativa / Texto | L9: https://portal.sat.gob.gt/portal/consulta-de-titulos-qr/
A10: 9 | B10: SAT-GES-0009 | C10: SAT-GES-0009 | D10: Solicitud de acceso a la información pública | H10: — | J10: Operación y declaraciones | K10: Guía Informativa / Texto | L10: https://portal.sat.gob.gt/portal/solicitud-informacion-publica/
A11: 10 | B11: SAT-GES-0010 | C11: SAT-GES-0010 | D11: Portal de acceso a la información pública | H11: — | J11: Operación y declaraciones | K11: Guía Informativa / Texto | L11: https://portal.sat.gob.gt/portal/libre-acceso-la-informacion-publica/
A12: 11 | B12: SAT-GES-0011 | C12: SAT-GES-0011 | D12: Solicitar tu NIT en línea | H12: — | J12: Modificaciones y cierre | K12: Guía Informativa / Texto | L12: https://portal.sat.gob.gt/portal/solicitud-electronica-de-nit/
A13: 12 | B13: SAT-GES-0012 | C13: SAT-GES-0012 | D13: Inscribirte como productor agropecuario, artesanal o de reciclaje | H13: — | J13: Modificaciones y cierre | K13: Guía Informativa / Texto | L13: https://portal.sat.gob.gt/portal/requisitos-tramites-agencia-virtual/inscripcion-en-el-registro-de-productores-de-productos-agropecuarios-artesanales-y-reciclados/
... A716: 715 | B716: SAT-GES-0683 | C716: SAT-GES-0683 | D716: Traspaso vehicular con exención para miembros del Cuerpo Diplomático y Consular | H716: — | J716: Operación y declaraciones | K716: Guía Informativa / Texto | L716: https://portal.sat.gob.gt/portal/requisitos-tramites-agencias/traspaso-diplomaticos/

Sheet Familias Temáticas (10)
A1: No. | B1: Código Canónico Oficial | C1: Identificador Técnico (Slug) | D1: Nombre Oficial de la Familia Temática | E1: Descripción del Ecosistema de Servicios | F1: Total Gestiones Canónicas Únicas | G1: % del Catálogo
A2: 1 | B2: FAM-01 | C2: fel | D2: Factura Electrónica en Línea (FEL) | E2: Ecosistema integral de emisión, certificación, anulación y consulta de documentos tributarios electrónicos. | F2: =COUNTIF('Catálogo Único (683)'!S2:S684, "*FAM-01*") | G2: =F2/683
A3: 2 | B3: FAM-02 | C3: vehiculos | D3: Registro Fiscal de Vehículos (RFV) | E3: Traspasos electrónicos, primeras placas, reposición de distintivos y pago del impuesto sobre circulación (ISCV). | F3: =COUNTIF('Catálogo Único (683)'!S2:S684, "*FAM-02*") | G3: =F3/683
A4: 3 | B4: FAM-03 | C4: rtu-digital | D4: Registro Tributario Unificado (RTU) Digital | E4: Inscripción de primer NIT, actualización periódica de datos y ratificación domiciliaria de contribuyentes. | F4: =COUNTIF('Catálogo Único (683)'!S2:S684, "*FAM-03*") | G4: =F4/683
A5: 4 | B5: FAM-04 | C5: ducas | D5: Declaraciones Aduaneras (DUCAs) | E5: Transmisión, despacho y liquidación electrónica de declaraciones aduaneras (DUCA-F, DUCA-D, DUCA-T). | F5: =COUNTIF('Catálogo Único (683)'!S2:S684, "*FAM-04*") | G5: =F5/683
A6: 5 | B6: FAM-05 | C6: solvencia-fiscal | D6: Solvencias y Convenios de Pago | E6: Acreditación de solvencia fiscal en línea, constancias de no deuda y convenios de facilidades de pago. | F6: =COUNTIF('Catálogo Único (683)'!S2:S684, "*FAM-05*") | G6: =F6/683
A7: 6 | B7: FAM-06 | C7: maquilas-29-89 | D7: Regímenes Especiales y Maquilas (Dto. 29-89) | E7: Fomento a la exportación, cuentas corrientes de insumos, garantías y descargos de maquila. | F7: =COUNTIF('Catálogo Único (683)'!S2:S684, "*FAM-06*") | G7: =F7/683
A8: 7 | B8: FAM-07 | C8: zdeep | D8: Zonas de Desarrollo Económico Especial Público (ZDEEP) | E8: Habilitación de polígonos, garitas aduaneras y régimen para empresas usuarias y administradoras de ZDEEP. | F8: =COUNTIF('Catálogo Único (683)'!S2:S684, "*FAM-07*") | G8: =F8/683
A9: 8 | B9: FAM-08 | C9: afpa | D9: Auxiliares de la Función Pública Aduanera (AFPA) | E9: Acreditación, carnés oficiales, garantías y régimen aduanero para agentes, apoderados, transportistas y couriers. | F9: =COUNTIF('Catálogo Único (683)'!S2:S684, "*FAM-08*") | G9: =F9/683
A10: 9 | B10: FAM-09 | C10: agencia-virtual | D10: Agencia Virtual y Servicios Remotos | E10: Activación, biometría, reseteo de claves y herramientas autenticadas de autogestión ciudadana. | F10: =COUNTIF('Catálogo Único (683)'!S2:S684, "*FAM-09*") | G10: =F10/683
A11: 10 | B11: FAM-10 | C11: exenciones | D11: Franquicias y Exenciones Tributarias | E11: Acreditación de exenciones diplomáticas, constancias de exención del IVA (CIVA) y donaciones oficiales. | F11: =COUNTIF('Catálogo Único (683)'!S2:S684, "*FAM-10*") | G11: =F11/683
