Workbook

Sheet Árbol de navegación
A1: Árbol de navegación por grupo, categoría y grupo de interés
A2: Nivel 1 = grupo de audiencia · Nivel 2 = categoría · Nivel 3 = grupo de la categoría. Los conteos se calculan desde cada hoja.
A4: Nivel 1 | B4: Nivel 2 · Categoría | C4: Nivel 3 · Grupo | D4: Páginas
A5: Contribuyentes | D5: =COUNTA(Contribuyentes!$G$5:$G$357) -> 353
B6: NIT sin Obligaciones | D6: =COUNTIF(Contribuyentes!$A$5:$A$357,B6) -> 5
C7: Todos los grupos | D7: =COUNTIFS(Contribuyentes!$A$5:$A$357,$B$6,Contribuyentes!$B$5:$B$357,C7) -> 5
B8: Pequeños Contribuyentes | D8: =COUNTIF(Contribuyentes!$A$5:$A$357,B8) -> 26
C9: Todos los grupos | D9: =COUNTIFS(Contribuyentes!$A$5:$A$357,$B$8,Contribuyentes!$B$5:$B$357,C9) -> 5
C10: Pequeño Contribuyente | D10: =COUNTIFS(Contribuyentes!$A$5:$A$357,$B$8,Contribuyentes!$B$5:$B$357,C10) -> 10
C11: Primario | D11: =COUNTIFS(Contribuyentes!$A$5:$A$357,$B$8,Contribuyentes!$B$5:$B$357,C11) -> 8
C12: Pecuario | D12: =COUNTIFS(Contribuyentes!$A$5:$A$357,$B$8,Contribuyentes!$B$5:$B$357,C12) -> 3
B13: Contribuyente General | D13: =COUNTIF(Contribuyentes!$A$5:$A$357,B13) -> 68
C14: Todos los grupos | D14: =COUNTIFS(Contribuyentes!$A$5:$A$357,$B$13,Contribuyentes!$B$5:$B$357,C14) -> 4
C15: Contribuyente General | D15: =COUNTIFS(Contribuyentes!$A$5:$A$357,$B$13,Contribuyentes!$B$5:$B$357,C15) -> 62
C16: Rep. Legales | D16: =COUNTIFS(Contribuyentes!$A$5:$A$357,$B$13,Contribuyentes!$B$5:$B$357,C16) -> 2
B17: Contribuyentes Especiales | D17: =COUNTIF(Contribuyentes!$A$5:$A$357,B17) -> 18
C18: Todos los grupos | D18: =COUNTIFS(Contribuyentes!$A$5:$A$357,$B$17,Contribuyentes!$B$5:$B$357,C18) -> 12
C19: Medianos | D19: =COUNTIFS(Contribuyentes!$A$5:$A$357,$B$17,Contribuyentes!$B$5:$B$357,C19) -> 0
C20: Grandes | D20: =COUNTIFS(Contribuyentes!$A$5:$A$357,$B$17,Contribuyentes!$B$5:$B$357,C20) -> 4
C21: Rep. Legales | D21: =COUNTIFS(Contribuyentes!$A$5:$A$357,$B$17,Contribuyentes!$B$5:$B$357,C21) -> 2
B22: Trámites comunes | D22: =COUNTIF(Contribuyentes!$A$5:$A$357,B22) -> 230
C23: Todos los grupos | D23: =COUNTIFS(Contribuyentes!$A$5:$A$357,$B$22,Contribuyentes!$B$5:$B$357,C23) -> 230
A24: Operadores de comercio exterior | D24: =COUNTA('Operadores de comercio exterior'!$F$5:$F$188) -> 184
B25: Importadores y Exportadores | D25: =COUNTIF('Operadores de comercio exterior'!$A$5:$A$188,B25) -> 75
C26: Todos los grupos | D26: =COUNTIFS('Operadores de comercio exterior'!$A$5:$A$188,$B$25,'Operadores de comercio exterior'!$B$5:$B$188,C26) -> 22
C27: Importadores | D27: =COUNTIFS('Operadores de comercio exterior'!$A$5:$A$188,$B$25,'Operadores de comercio exterior'!$B$5:$B$188,C27) -> 27
C28: OEA | D28: =COUNTIFS('Operadores de comercio exterior'!$A$5:$A$188,$B$25,'Operadores de comercio exterior'!$B$5:$B$188,C28) -> 5
C29: Exportadores | D29: =COUNTIFS('Operadores de comercio exterior'!$A$5:$A$188,$B$25,'Operadores de comercio exterior'!$B$5:$B$188,C29) -> 21
B30: Auxiliares de la Función Pública Aduanera | D30: =COUNTIF('Operadores de comercio exterior'!$A$5:$A$188,B30) -> 35
C31: Todos los grupos | D31: =COUNTIFS('Operadores de comercio exterior'!$A$5:$A$188,$B$30,'Operadores de comercio exterior'!$B$5:$B$188,C31) -> 8
C32: Courier | D32: =COUNTIFS('Operadores de comercio exterior'!$A$5:$A$188,$B$30,'Operadores de comercio exterior'!$B$5:$B$188,C32) -> 3
C33: Consolidadores y Desconsolidadores de Carga | D33: =COUNTIFS('Operadores de comercio exterior'!$A$5:$A$188,$B$30,'Operadores de comercio exterior'!$B$5:$B$188,C33) -> 2
C34: Almacenes Fiscales | D34: =COUNTIFS('Operadores de comercio exterior'!$A$5:$A$188,$B$30,'Operadores de comercio exterior'!$B$5:$B$188,C34) -> 1
C35: Almacenadoras | D35: =COUNTIFS('Operadores de comercio exterior'!$A$5:$A$188,$B$30,'Operadores de comercio exterior'!$B$5:$B$188,C35) -> 1
C36: Depósitos Aduaneros | D36: =COUNTIFS('Operadores de comercio exterior'!$A$5:$A$188,$B$30,'Operadores de comercio exterior'!$B$5:$B$188,C36) -> 1
C37: ZDEEP | D37: =COUNTIFS('Operadores de comercio exterior'!$A$5:$A$188,$B$30,'Operadores de comercio exterior'!$B$5:$B$188,C37) -> 0
C38: Agentes Aduaneros | D38: =COUNTIFS('Operadores de comercio exterior'!$A$5:$A$188,$B$30,'Operadores de comercio exterior'!$B$5:$B$188,C38) -> 6
C39: Transportistas | D39: =COUNTIFS('Operadores de comercio exterior'!$A$5:$A$188,$B$30,'Operadores de comercio exterior'!$B$5:$B$188,C39) -> 13
C40: Apoderado Especial Aduanero | D40: =COUNTIFS('Operadores de comercio exterior'!$A$5:$A$188,$B$30,'Operadores de comercio exterior'!$B$5:$B$188,C40) -> 0
B41: Trámites comunes | D41: =COUNTIF('Operadores de comercio exterior'!$A$5:$A$188,B41) -> 74
...

Sheet Descripciones
A1: Descripciones de categorías y grupos
A2: Para qué sirve cada nivel desde el portal SAT y la base legal de referencia (verificar contra la versión vigente de cada ley).
A4: Nivel 1 | B4: Categoría | C4: Grupo | D4: Para quién es | E4: Base legal de referencia | F4: Páginas
A5: Contribuyentes | D5: Personas y empresas inscritas en el RTU: inscripción, declaraciones, facturas, vehículos, devoluciones y más. | E5: Código Tributario (Decreto 6-91): Registro Tributario Unificado. | F5: =COUNTA(Contribuyentes!$G$5:$G$357) -> 353
A6: Contribuyentes | B6: NIT sin Obligaciones | D6: Personas con NIT que no están afiliadas a impuestos: asalariados, personas que compran bienes o hacen trámites de vehículos y profesionales que registran su título. | E6: Código Tributario (RTU); Ley de Actualización Tributaria (Decreto 10-2012), ISR de rentas del trabajo. | F6: =COUNTIF(Contribuyentes!$A$5:$A$357,B6) -> 5
A7: Contribuyentes | B7: Pequeños Contribuyentes | D7: Contribuyentes de regímenes simplificados: pequeño contribuyente y los nuevos regímenes del sector primario y pecuario. | E7: Ley del IVA (Decreto 27-92), Régimen de Pequeño Contribuyente; Decreto 31-2024. | F7: =COUNTIF(Contribuyentes!$A$5:$A$357,B7) -> 26
A8: Contribuyentes | B8: Pequeños Contribuyentes | C8: Pequeño Contribuyente | D8: Personas con ingresos anuales de hasta Q150,000 que pagan una tarifa única sobre sus ventas (incluye el Régimen Electrónico). | E8: Ley del IVA (Decreto 27-92), Régimen de Pequeño Contribuyente; Decreto 7-2019 (régimen electrónico). | F8: =COUNTIFS(Contribuyentes!$A$5:$A$357,B8,Contribuyentes!$B$5:$B$357,C8) -> 10
A9: Contribuyentes | B9: Pequeños Contribuyentes | C9: Primario | D9: Productores agrícolas y artesanales del sector primario inscritos en el régimen especial, con pago del Impuesto a la Confianza Tributaria (ICT). | E9: Ley para la Integración del Sector Productivo Primario y Agropecuario (Decreto 31-2024). | F9: =COUNTIFS(Contribuyentes!$A$5:$A$357,B9,Contribuyentes!$B$5:$B$357,C9) -> 8
A10: Contribuyentes | B10: Pequeños Contribuyentes | C10: Pecuario | D10: Productores e intermediarios de ganado, acuicultura y apicultura sin transformación industrial, inscritos en el régimen pecuario (ICT). | E10: Decreto 31-2024, régimen pecuario. | F10: =COUNTIFS(Contribuyentes!$A$5:$A$357,B10,Contribuyentes!$B$5:$B$357,C10) -> 3
A11: Contribuyentes | B11: Contribuyente General | D11: Contribuyentes del Régimen General del IVA y del ISR de actividades lucrativas (sobre utilidades u opcional simplificado), incluidas personas jurídicas y entes. | E11: Ley del IVA (Decreto 27-92); Ley de Actualización Tributaria (Decreto 10-2012). | F11: =COUNTIF(Contribuyentes!$A$5:$A$357,B11) -> 68
A12: Contribuyentes | B12: Contribuyente General | C12: Contribuyente General | D12: Personas individuales y jurídicas con negocio en el Régimen General. | E12: Decreto 27-92 y Decreto 10-2012. | F12: =COUNTIFS(Contribuyentes!$A$5:$A$357,B12,Contribuyentes!$B$5:$B$357,C12) -> 62
A13: Contribuyentes | B13: Contribuyente General | C13: Rep. Legales | D13: Representantes legales que hacen gestiones en nombre de personas jurídicas. | E13: Código Tributario, responsables por representación; Código de Comercio. | F13: =COUNTIFS(Contribuyentes!$A$5:$A$357,B13,Contribuyentes!$B$5:$B$357,C13) -> 2
A14: Contribuyentes | B14: Contribuyentes Especiales | D14: Contribuyentes calificados por la SAT como especiales por su volumen de operaciones; atención en gerencias especializadas. | E14: Calificación por resolución de la SAT (Ley Orgánica de la SAT, Decreto 1-98). | F14: =COUNTIF(Contribuyentes!$A$5:$A$357,B14) -> 18
A15: Contribuyentes | B15: Contribuyentes Especiales | C15: Medianos | D15: Contribuyentes especiales medianos. | E15: Resolución de calificación de la SAT. | F15: =COUNTIFS(Contribuyentes!$A$5:$A$357,B15,Contribuyentes!$B$5:$B$357,C15) -> 0
A16: Contribuyentes | B16: Contribuyentes Especiales | C16: Grandes | D16: Contribuyentes especiales grandes. | E16: Resolución de calificación de la SAT. | F16: =COUNTIFS(Contribuyentes!$A$5:$A$357,B16,Contribuyentes!$B$5:$B$357,C16) -> 4
A17: Contribuyentes | B17: Contribuyentes Especiales | C17: Rep. Legales | D17: Representantes legales de contribuyentes especiales. | E17: Código Tributario, responsables por representación. | F17: =COUNTIFS(Contribuyentes!$A$5:$A$357,B17,Contribuyentes!$B$5:$B$357,C17) -> 2
A18: Operadores de comercio exterior | D18: Personas que importan, exportan o prestan servicios en las operaciones aduaneras. | E18: CAUCA y RECAUCA; Ley Nacional de Aduanas (Decreto 14-2013). | F18: =COUNTA('Operadores de comercio exterior'!$F$5:$F$188) -> 184
A19: Operadores de comercio exterior | B19: Importadores y Exportadores | D19: Personas y empresas que importan o exportan mercancías. | E19: CAUCA y RECAUCA; Ley del IVA (devolución de crédito fiscal). | F19: =COUNTIF('Operadores de comercio exterior'!$A$5:$A$188,B19) -> 75
A20: Operadores de comercio exterior | B20: Importadores y Exportadores | C20: Importadores | D20: Quienes ingresan mercancías o vehículos al país. | E20: CAUCA y RECAUCA. | F20: =COUNTIFS('Operadores de comercio exterior'!$A$5:$A$188,B20,'Operadores de comercio exterior'!$B$5:$B$188,C20) -> 27
A21: Operadores de comercio exterior | B21: Importadores y Exportadores | C21: OEA | D21: Operadores Económicos Autorizados: empresas certificadas por cumplir estándares de seguridad y bajo riesgo. | E21: CAUCA y RECAUCA; programa OEA de la SAT. | F21: =COUNTIFS('Operadores de comercio exterior'!$A$5:$A$188,B21,'Operadores de comercio exterior'!$B$5:$B$188,C21) -> 5
A22: Operadores de comercio exterior | B22: Importadores y Exportadores | C22: Exportadores | D22: Quienes venden mercancías al exterior: registro de exportadores y devolución del crédito fiscal del IVA. | E22: Ley del IVA (Decreto 27-92), regímenes de devolución de crédito fiscal. | F22: =COUNTIFS('Operadores de comercio exterior'!$A$5:$A$188,B22,'Operadores de comercio exterior'!$B$5:$B$188,C22) -> 21
A23: Operadores de comercio exterior | B23: Auxiliares de la Función Pública Aduanera | D23: Personas autorizadas por la SAT que intervienen en las operaciones aduaneras. | E23: CAUCA y RECAUCA, auxiliares de la función pública aduanera; Decreto 14-2013. | F23: =COUNTIF('Operadores de comercio exterior'!$A$5:$A$188,B23) -> 35
A24: Operadores de comercio exterior | B24: Auxiliares de la Función Pública Aduanera | C24: Courier | D24: Empresas de entrega rápida. | E24: RECAUCA. | F24: =COUNTIFS('Operadores de comercio exterior'!$A$5:$A$188,B24,'Operadores de comercio exterior'!$B$5:$B$188,C24) -> 3
A25: Operadores de comercio exterior | B25: Auxiliares de la Función Pública Aduanera | C25: Consolidadores y Desconsolidadores de Carga | D25: Agrupan o separan carga de varios consignatarios. | E25: RECAUCA. | F25: =COUNTIFS('Operadores de comercio exterior'!$A$5:$A$188,B25,'Operadores de comercio exterior'!$B$5:$B$188,C25) -> 2
A26: Operadores de comercio exterior | B26: Auxiliares de la Función Pública Aduanera | C26: Almacenes Fiscales | D26: Depositarios aduaneros que almacenan mercancías bajo control aduanero. | E26: RECAUCA. | F26: =COUNTIFS('Operadores de comercio exterior'!$A$5:$A$188,B26,'Operadores de comercio exterior'!$B$5:$B$188,C26) -> 1
A27: Operadores de comercio exterior | B27: Auxiliares de la Función Pública Aduanera | C27: Almacenadoras | D27: Almacenes generales de depósito autorizados. | E27: RECAUCA. | F27: =COUNTIFS('Operadores de comercio exterior'!$A$5:$A$188,B27,'Operadores de comercio exterior'!$B$5:$B$188,C27) -> 1
A28: Operadores de comercio exterior | B28: Auxiliares de la Función Pública Aduanera | C28: Depósitos Aduaneros | D28: Depósitos autorizados para mercancías en régimen suspensivo. | E28: RECAUCA. | F28: =COUNTIFS('Operadores de comercio exterior'!$A$5:$A$188,B28,'Operadores de comercio exterior'!$B$5:$B$188,C28) -> 1
A29: Operadores de comercio exterior | B29: Auxiliares de la Función Pública Aduanera | C29: ZDEEP | D29: Desarrolladores de Zonas de Desarrollo Económico Especial Públicas, registrados como auxiliares. | E29: Decreto 22-73 (ZOLIC), reformado por Decreto 30-2008. | F29: =COUNTIFS('Operadores de comercio exterior'!$A$5:$A$188,B29,'Operadores de comercio exterior'!$B$5:$B$188,C29) -> 0
A30: Operadores de comercio exterior | B30: Auxiliares de la Función Pública Aduanera | C30: Agentes Aduaneros | D30: Profesionales autorizados para presentar declaraciones de mercancías por cuenta de terceros. | E30: CAUCA y RECAUCA. | F30: =COUNTIFS('Operadores de comercio exterior'!$A$5:$A$188,B30,'Operadores de comercio exterior'!$B$5:$B$188,C30) -> 6
A31: Operadores de comercio exterior | B31: Auxiliares de la Función Pública Aduanera | C31: Transportistas | D31: Transportistas aduaneros: manifiestos, marchamo y tránsito. | E31: CAUCA y RECAUCA. | F31: =COUNTIFS('Operadores de comercio exterior'!$A$5:$A$188,B31,'Operadores de comercio exterior'!$B$5:$B$188,C31) -> 13
A32: Operadores de comercio exterior | B32: Auxiliares de la Función Pública Aduanera | C32: Apoderado Especial Aduanero | D32: Representante del importador o exportador en sus propias operaciones. | E32: Ley Nacional de Aduanas (Decreto 14-2013). | F32: =COUNTIFS('Operadores de comercio exterior'!$A$5:$A$188,B32,'Operadores de comercio exterior'!$B$5:$B$188,C32) -> 0
A33: Profesionales | D33: Personas que hacen gestiones ante la SAT por cuenta de otros. | F33: =COUNTA(Profesionales!$F$5:$F$95) -> 91
A34: Profesionales | B34: Terceras Personas | D34: Terceras personas autorizadas o registradas ante la SAT. | F34: =COUNTIF(Profesionales!$A$5:$A$95,B34) -> 91
A35: Profesionales | B35: Terceras Personas | C35: Gestores Tributarios | D35: Personas autorizadas por la SAT para hacer gestiones de terceros, principalmente de vehículos. | E35: Registro y autorización de la SAT. | F35: =COUNTIFS(Profesionales!$A$5:$A$95,B35,Profesionales!$B$5:$B$95,C35) -> 5
A36: Profesionales | B36: Terceras Personas | C36: Auxiliar Tributario | D36: Auxiliares de los gestores tributarios. | E36: Registro y autorización de la SAT. | F36: =COUNTIFS(Profesionales!$A$5:$A$95,B36,Profesionales!$B$5:$B$95,C36) -> 3
A37: Profesionales | B37: Terceras Personas | C37: Abogados y Notarios | D37: Registro de abogados y notarios, avisos notariales, traspasos electrónicos y especies fiscales. | E37: Código de Notariado (Decreto 314); Ley del Impuesto de Timbres Fiscales (Decreto 37-92). | F37: =COUNTIFS(Profesionales!$A$5:$A$95,B37,Profesionales!$B$5:$B$95,C37) -> 14
A38: Profesionales | B38: Terceras Personas | C38: Peritos Contadores | D38: Contadores inscritos que llevan la contabilidad de los contribuyentes. | E38: Decreto 10-2012 (contabilidad); Código de Comercio. | F38: =COUNTIFS(Profesionales!$A$5:$A$95,B38,Profesionales!$B$5:$B$95,C38) -> 8
A39: Profesionales | B39: Terceras Personas | C39: Auditores | D39: Contadores públicos y auditores que emiten dictámenes ante la SAT. | E39: Decreto 10-2012; Ley del IVA (dictamen para devolución de crédito fiscal). | F39: =COUNTIFS(Profesionales!$A$5:$A$95,B39,Profesionales!$B$5:$B$95,C39) -> 8
A40: Organismos especiales | D40: Entidades con régimen especial de exención y entidades del Estado. | F40: =COUNTA('Organismos especiales'!$F$5:$F$138) -> 134
A41: Organismos especiales | B41: Exentos | D41: Entidades exentas de impuestos según la Constitución o leyes específicas. | E41: Constitución Política; Decreto 10-2012, art. 11 (rentas exentas). | F41: =COUNTIF('Organismos especiales'!$A$5:$A$138,B41) -> 99
...

Sheet Contribuyentes
A1: Contribuyentes
A2: Personas individuales y jurídicas inscritas en el RTU, ordenadas por categoría (régimen o tipo de contribuyente) y grupo. Orden: Categoría › Grupo › Tema › Página. «Todos los grupos» = la usan todos los grupos de la categoría. «Trámites comunes» = la usan varias categorías.
A4: Macro Grupos | B4: Grupo | C4: Sub grupo | D4: Tema | E4: Subtema | F4: Página / Trámite (nombre actual) | G4: Nombre de trámite sugerido | H4: Descripción de la página | I4: Usado por (según Grupos y categorías) | J4: Origen de la clasificación | K4: Motivo / referencia | L4: Sección actual del menú | M4: URL | N4: Nota / Revisar
A5: Contribuyente General | B5: Todos los grupos | D5: Devoluciones y créditos fiscales | E5: ISR (Impuesto Sobre la Renta) | F5: Devolución de ISR Asalariados (Retenciones en exceso o pago indebido) SAT-117 o 1431 | G5: Devolución de ISR si eres asalariado | H5: Información sobre: Devolución de ISR si eres asalariado. | J5: Análisis | K5: Asalariados: NIT sin obligaciones, ISR de rentas del trabajo | L5: SERVICIOS TRIBUTARIOS | M5: https://portal.sat.gob.gt/portal/requisitos-tramites-agencias/devolucion-del-impuesto-sobre-la-renta-asalariados-retenciones-en-exceso-o-pago-indebido/ | N5: Servicio/tema general para contribuyentes
A6: Contribuyentes | B6: NIT sin Obligaciones | D6: RTU Digital | E6: Inscripción | F6: Requisitos para la Inscripción RTU | G6: Inscripción de NIT sin Obligaciones | H6: Solicitud y requisitos para la obtención electrónica de NIT sin obligaciones tributarias por primera vez. | I6: Personas Individuales (Nacionales y Extranjeros sin actividad económica) | J6: Análisis de arquitectura transaccional | K6: Trámite inicial obligatorio para actos civiles, apertura de cuentas bancarias y recepción de remesas. | L6: Requisitos de personas / empresas | M6: https://portal.sat.gob.gt/portal/requisitos-de-personas-empresas/#1615485066841-639e67c5-51e3 | N6: Desvincular del listado de empresas/sociedades mercantiles; crear landing o ficha específica para personas individuales.
A7: Contribuyentes | B7: NIT sin Obligaciones | D7: RTU Digital | E7: Actualización | F7: Requisitos para la Actualización RTU | G7: Actualización de Datos y Transición de Régimen | H7: Requisitos y pasos para actualizar datos de identificación, domicilio fiscal o pasar al régimen con obligaciones tributarias. | I7: Personas que inician relación laboral o comercial | J7: Análisis de arquitectura transaccional | K7: Permite modificar datos personales o dar el salto formal a contribuyente afecto cuando la persona inicia actividades económicas. | L7: Requisitos de personas / empresas | M7: https://portal.sat.gob.gt/portal/requisitos-de-personas-empresas/#1541621044169-4198d06d-693f | N7: Aislar la opción de paso de 'sin obligaciones' a 'con obligaciones' sin obligar a navegar por requisitos corporativos.
A8: Contribuyentes | B8: NIT sin Obligaciones | D8: Sistemas Web | E8: Acceso y Seguridad | F8: Agencia Virtual | G8: Solicitud y Activación de Agencia Virtual | H8: Acceso a plataforma, activación de usuario, reinicio de contraseña y cambio de correo electrónico para personas sin obligaciones. | I8: Usuarios registrados con NIT | J8: Análisis de arquitectura transaccional | K8: Canal indispensable para descargar la constancia de RTU, consultar datos personales y dar seguimiento a solicitudes web. | L8: Menú Principal / Sistemas | M8: https://farm3.sat.gob.gt/menu/login.jsf | N8: Es un sistema de autenticación directa; la ficha informativa debe explicar cómo obtener el acceso inicial.
A9: Contribuyentes | B9: NIT sin Obligaciones | D9: Consultas Públicas | E9: Seguimiento | F9: Estado de Gestión de Agencia Virtual | G9: Consulta de Estado de Gestión de Agencia Virtual | H9: Herramienta de consulta para verificar el estado de aprobación de la solicitud de acceso a Agencia Virtual. | I9: Solicitantes de Agencia Virtual | J9: Análisis de arquitectura transaccional | K9: Permite validar si la solicitud de usuario o reseteo de clave fue aceptada, rechazada o requiere subsanar requisitos. | L9: Consultas Públicas | M9: https://portal.sat.gob.gt/portal/consulta-de-gestion-del-contribuyente/ | N9: Debe integrarse como paso de seguimiento dentro de la ficha de Agencia Virtual, no como enlace huérfano.
A10: Contribuyentes | B10: NIT sin Obligaciones | D10: Certificaciones | E10: Solvencias | F10: Solvencia Fiscal | G10: Solicitud y Emisión de Solvencia Fiscal (SOFI) | H10: Consulta, pago y descarga de la Solvencia Fiscal Electrónica para certificar ausencia de adeudos tributarios. | I10: Personas Individuales | J10: Análisis de arquitectura transaccional | K10: Exigida comúnmente a personas sin obligaciones para postulaciones laborales, trámites consulares/visas y contratos civiles. | L10: Consultas / Solvencias | M10: https://portal.sat.gob.gt/portal/solvencia-fiscal/ | N10: Para este perfil la emisión es automática, salvo que existan registros históricos de omisos o adeudos en el ISCV.
A11: Contribuyentes | B11: NIT sin Obligaciones | D11: Citas y Agencias | E11: Citas | F11: Requisitos para la Atención a través de Cita | G11: Cita Previa para Trámites Presenciales | H11: Información, requisitos y agenda electrónica para programar atención física en agencias tributarias. | I11: Casos especiales (menores o extranjeros) | J11: Análisis de arquitectura transaccional | K11: Aplica a personas sin obligaciones únicamente en validaciones biométricas presenciales o trámites mediante representante legal. | L11: Requisitos trámites agencias | M11: https://portal.sat.gob.gt/portal/requisitos-tramites-agencias/cita-controlada/ | N11: Condicional: solo debe desplegarse como alternativa si el trámite inicial no logra completarse 100% en línea.
A12: NIT sin Obligaciones | B12: Todos los grupos | D12: Otros servicios al contribuyente | E12: Títulos universitarios | F12: Títulos Universitarios | G12: Información sobre títulos universitarios | H12: Información sobre: Información sobre títulos universitarios. | J12: Análisis | K12: Profesionales que registran su título (NIT sin obligaciones) | L12: SERVICIOS TRIBUTARIOS | M12: https://portal.sat.gob.gt/portal/titulos-universitarios/ | N12: Servicio/tema general para contribuyentes
A13: NIT sin Obligaciones | B13: Todos los grupos | D13: Otros servicios al contribuyente | E13: Títulos universitarios | F13: Registro y Habilitación de Títulos Universitarios | G13: Registrar tu título universitario para ejercer | H13: Requisitos, pasos y documentos para registrar tu título universitario para ejercer. | I13: NIT sin Obligaciones | J13: Grupos y categorías | K13: Marcada «SI» en el archivo Grupos y categorías | L13: SERVICIOS TRIBUTARIOS | M13: https://portal.sat.gob.gt/portal/requisitos-tramites-agencias/registro-y-habilitacion-de-titulos-para-ejercer-profesion/ | N13: Servicio/tema general para contribuyentes
A14: NIT sin Obligaciones | B14: Todos los grupos | D14: Vehículos (como propietario) | E14: Requisitos y representantes | F14: Temas De Vehiculos | G14: Preguntas frecuentes sobre vehículos | H14: Respuestas a las preguntas más comunes sobre requisitos y representantes. | I14: NIT sin Obligaciones | J14: Grupos y categorías | K14: Marcada «SI» en el archivo Grupos y categorías | L14: CAPACITACIÓN | M14: https://portal.sat.gob.gt/portal/preguntas-frecuentes/temas-de-vehiculos/ | N14: Servicio/tema general para contribuyentes
A15: NIT sin Obligaciones | B15: Todos los grupos | D15: Vehículos (como propietario) | E15: Título y tarjeta de circulación | F15: Distintivos Electrónicos (Título de propiedad y Tarjeta de Circulación) | G15: Título y tarjeta de circulación electrónicos | H15: Información sobre: Título y tarjeta de circulación electrónicos. | I15: NIT sin Obligaciones | J15: Grupos y categorías | K15: Marcada «SI» en el archivo Grupos y categorías | L15: SERVICIOS TRIBUTARIOS | M15: https://portal.sat.gob.gt/portal/distintivos-electronicos/ | N15: Servicio/tema general para contribuyentes
A16: NIT sin Obligaciones | B16: Todos los grupos | D16: Agregada desde «Grupos y categorías» | G16: Libro Electrónico Tributario | H16: Pequeño Contribuyente | I16: NIT sin Obligaciones | J16: Grupos y categorías | K16: Marcada «SI» en el archivo Grupos y categorías | M16: https://portal.sat.gob.gt/portal/libro-electronico-tributario/pequeno-contribuyente/
A17: Pequeños Contribuyentes | B17: Todos los grupos | D17: Cultura tributaria y capacitación | E17: Leyes y normativa | F17: Legislación | G17: Legislación | H17: Información sobre: Legislación. | I17: Pequeños Contribuyentes | J17: Grupos y categorías | K17: Marcada «SI» en el archivo Grupos y categorías | L17: CAPACITACIÓN | M17: https://portal.sat.gob.gt/portal/biblioteca-en-linea-sat/legislacion/ | N17: Servicio/tema general para contribuyentes
A18: Pequeños Contribuyentes | B18: Todos los grupos | D18: Facturación electrónica y documentos tributarios | E18: Constancias de retención | F18: Constancias de Retención del IVA e ISR recibidos | G18: Consultar constancias de retención de IVA e ISR recibidas | H18: Servicio en línea para consultar constancias de retención de IVA e ISR recibidas. | I18: Pequeños Contribuyentes | J18: Grupos y categorías | K18: Marcada «SI» en el archivo Grupos y categorías | L18: SERVICIOS TRIBUTARIOS | M18: https://portal.sat.gob.gt/portal/retenciones-del-iva-consulta-de-constancias-de-retencion-del-iva-recibidas/ | N18: Servicio/tema general para contribuyentes
A19: Pequeños Contribuyentes | B19: Todos los grupos | D19: Importación | E19: Proceso de importación | F19: Despacho de distintivos de control de productos importados a los fabricantes o importadores domiciliados en el país y a las personas individuales y jurídicas que no sean fabricantes ni importadores | G19: Obtener distintivos de control de productos importados | H19: Requisitos, pasos y documentos para obtener distintivos de control de productos importados. | I19: Pequeños Contribuyentes | J19: Grupos y categorías | K19: Marcada «SI» en el archivo Grupos y categorías | L19: SERVICIOS TRIBUTARIOS | M19: https://portal.sat.gob.gt/portal/requisitos-tramites-agencias/despacho-de-distintivos-de-control-de-productos-importados-a-los-fabricantes-o-importadores-domiciliados-en-el-pais-y-a-las-personas-individuales-y-juridicas/ | N19: Coincide con palabra clave de comercio exterior/aduanas
A20: Pequeños Contribuyentes | B20: Todos los grupos | D20: Inscripción y actualización en el RTU | E20: Obtener o corregir tu NIT | F20: Solicitud Electrónica de NIT | G20: Solicitar tu NIT en línea | H20: Requisitos, pasos y documentos para solicitar tu NIT en línea. | I20: Pequeños Contribuyentes | J20: Grupos y categorías | K20: Marcada «SI» en el archivo Grupos y categorías | L20: SERVICIOS TRIBUTARIOS | M20: https://portal.sat.gob.gt/portal/solicitud-electronica-de-nit/ | N20: Servicio/tema general para contribuyentes
A21: Pequeños Contribuyentes | B21: Todos los grupos | D21: Otros servicios al contribuyente | E21: Sistemas de retención | F21: Asiste Hospitales Web | G21: Retenciones de hospitales (Asiste Hospitales Web) | H21: Información sobre: Retenciones de hospitales (Asiste Hospitales Web). | I21: Pequeños Contribuyentes | J21: Grupos y categorías | K21: Marcada «SI» en el archivo Grupos y categorías | L21: SERVICIOS TRIBUTARIOS | M21: https://portal.sat.gob.gt/portal/sistemas-web/asistehospitalesweb/ | N21: Servicio/tema general para contribuyentes
A22: Pequeños Contribuyentes | B22: Pequeño Contribuyente | D22: Cultura tributaria y capacitación | E22: Cursos por tipo de contribuyente | F22: Principales obligaciones tributarias de los pequeños contribuyentes | G22: Curso: obligaciones del pequeño contribuyente | H22: Capacitación virtual de la SAT sobre obligaciones del pequeño contribuyente. | J22: Análisis | K22: Régimen de Pequeño Contribuyente (Ley del IVA) | L22: CAPACITACIÓN | M22: https://sites.google.com/capacitacionessat.page/cultura-tributariad/cursos-virtuales-sat/impuesto-al-valor-agregado-iva/r%C3%A9gimen-del-peque%C3%B1o-contribuyente | N22: Servicio/tema general para contribuyentes
A23: Pequeños Contribuyentes | B23: Pequeño Contribuyente | D23: Devoluciones y créditos fiscales | E23: ISR (Impuesto Sobre la Renta) | F23: Devolución o Compensación del Impuesto Sobre la Renta Retenido al Pequeño Contribuyente del 5% | G23: Devolución del 5% de ISR retenido al pequeño contribuyente | H23: Información sobre: Devolución del 5% de ISR retenido al pequeño contribuyente. | J23: Análisis | K23: Retención de ISR al pequeño contribuyente | L23: SERVICIOS TRIBUTARIOS | M23: https://portal.sat.gob.gt/portal/requisitos-tramites-agencias/devolucion-acreditamiento-o-compensacion-de-impuesto-sobre-la-renta-retenido-indebidamente-a-pequeno-contribuyente-del-5/ | N23: Servicio/tema general para contribuyentes
A24: Pequeños Contribuyentes | B24: Pequeño Contribuyente | D24: Facturación electrónica y documentos tributarios | E24: Libro Electrónico Tributario (LET) | F24: Libro Electrónico Tributario para Pequeño contribuyente | G24: Curso: LET para pequeño contribuyente | H24: Capacitación virtual de la SAT sobre LET para pequeño contribuyente. | J24: Análisis | K24: Libro Electrónico Tributario del pequeño contribuyente | L24: CAPACITACIÓN | M24: https://sites.google.com/capacitacionessat.page/eventosenvivo/p%C3%A1gina-principal/libro-electr%C3%B3nico-tributario-para-peque%C3%B1o-contribuyente | N24: Servicio/tema general para contribuyentes
A25: Pequeños Contribuyentes | B25: Pequeño Contribuyente | D25: Otros servicios al contribuyente | E25: Libros, facturas y máquinas | F25: Autorización de documentos tributarios a pequeños contribuyentes | G25: Autorizar documentos para pequeños contribuyentes | H25: Requisitos, pasos y documentos para autorizar documentos para pequeños contribuyentes. | J25: Análisis | K25: Documentos del pequeño contribuyente | L25: SERVICIOS TRIBUTARIOS | M25: https://portal.sat.gob.gt/portal/requisitos-tramites-agencias/autorizacion-de-documentos-tributarios-a-pequenos-contribuyentes/ | N25: Servicio/tema general para contribuyentes
A26: Pequeños Contribuyentes | B26: Pequeño Contribuyente | D26: Regímenes tributarios | E26: Cambio de régimen | F26: Actualización de Cambio de Régimen de Pequeño Contribuyente a Régimen Electrónico de Pequeño Contribuyente | G26: Pasar a Régimen Electrónico de Pequeño Contribuyente | H26: Requisitos, pasos y documentos para pasar a Régimen Electrónico de Pequeño Contribuyente. | J26: Análisis | K26: Régimen de Pequeño Contribuyente (Ley del IVA) | L26: SERVICIOS TRIBUTARIOS | M26: https://portal.sat.gob.gt/portal/requisitos-tramites-agencias/requisitos-de-actualizacion-de-cambio-de-regimen-general-a-pequeno-contribuyente-persona/ | N26: Servicio/tema general para contribuyentes
A27: Pequeños Contribuyentes | B27: Pequeño Contribuyente | D27: Regímenes tributarios | E27: Cambio de régimen | F27: Actualización Cambio de Régimen de Pequeño Contribuyente a Régimen General del Impuesto al Valor Agregado | G27: Pasar de Pequeño Contribuyente a Régimen General del IVA | H27: Requisitos, pasos y documentos para pasar de Pequeño Contribuyente a Régimen General del IVA. | J27: Análisis | K27: Régimen de Pequeño Contribuyente (Ley del IVA) | L27: SERVICIOS TRIBUTARIOS | M27: https://portal.sat.gob.gt/portal/requisitos-tramites-agencias/actualizacion-cambio-de-regimen-de-pequeno-contribuyente-a-regimen-general-del-impuesto-al-valor-agregado/ | N27: Servicio/tema general para contribuyentes
A28: Pequeños Contribuyentes | B28: Pequeño Contribuyente | D28: Regímenes tributarios | E28: Pequeño Contribuyente | F28: Consulta NIT de Pequeño Contribuyente | G28: Consultar si un NIT es Pequeño Contribuyente | H28: Servicio en línea para consultar si un NIT es Pequeño Contribuyente. | J28: Análisis | K28: Régimen de Pequeño Contribuyente (Ley del IVA) | L28: SERVICIOS TRIBUTARIOS | M28: https://portal.sat.gob.gt/portal/consulta-regimen-de-pequeno-contribuyente/ | N28: Servicio/tema general para contribuyentes
A29: Pequeños Contribuyentes | B29: Pequeño Contribuyente | D29: Regímenes tributarios | E29: Pequeño Contribuyente | F29: Régimen Electrónico de Pequeño Contribuyente | G29: Curso: Régimen Electrónico de Pequeño Contribuyente | H29: Capacitación virtual de la SAT sobre Régimen Electrónico de Pequeño Contribuyente. | J29: Análisis | K29: Régimen de Pequeño Contribuyente (Ley del IVA) | L29: CAPACITACIÓN | M29: https://sites.google.com/capacitacionessat.page/cultura-tributariad/cursos-virtuales-sat/impuesto-al-valor-agregado-iva/r%C3%A9gimen-electr%C3%B3nico-de-peque%C3%B1o-contribuyente | N29: Servicio/tema general para contribuyentes
A30: Pequeños Contribuyentes | B30: Pequeño Contribuyente | D30: Regímenes tributarios | E30: Pequeño Contribuyente | F30: Régimen Electrónico del Pequeño Contribuyente | G30: Curso: Régimen Electrónico de Pequeño Contribuyente | H30: Capacitación virtual de la SAT sobre Régimen Electrónico de Pequeño Contribuyente. | J30: Análisis | K30: Régimen de Pequeño Contribuyente (Ley del IVA) | L30: CAPACITACIÓN | M30: https://sites.google.com/capacitacionessat.page/eventosenvivo/p%C3%A1gina-principal/r%C3%A9gimen-electr%C3%B3nico-del-peque%C3%B1o-contribuyente | N30: Servicio/tema general para contribuyentes
A31: Pequeños Contribuyentes | B31: Pequeño Contribuyente | D31: Regímenes tributarios | E31: Pequeño Contribuyente | F31: Régimen del pequeño contribuyente | G31: Curso: régimen de Pequeño Contribuyente | H31: Capacitación virtual de la SAT sobre régimen de Pequeño Contribuyente. | J31: Análisis | K31: Régimen de Pequeño Contribuyente (Ley del IVA) | L31: CAPACITACIÓN | M31: https://sites.google.com/capacitacionessat.page/cultura-tributariad/cursos-virtuales-sat/impuesto-al-valor-agregado/r%C3%A9gimen-del-peque%C3%B1o-contribuyente | N31: Servicio/tema general para contribuyentes
A32: Pequeños Contribuyentes | B32: Primario | D32: Consultas y verificadores | E32: Registros públicos | F32: Productores Inscritos: Consulta Productores | G32: Consultar productores inscritos | H32: Servicio en línea para consultar productores inscritos. | J32: Análisis | K32: Registro de productores | L32: SERVICIOS TRIBUTARIOS | M32: https://portal.sat.gob.gt/portal/consulta-productores/ | N32: Servicio/tema general para contribuyentes
A33: Pequeños Contribuyentes | B33: Primario | D33: Cultura tributaria y capacitación | E33: Cursos por tipo de contribuyente | F33: Productores de Productos Agropecuarios, Artesanales y Reciclados | G33: Curso: productores agropecuarios, artesanales y de reciclaje | H33: Capacitación virtual de la SAT sobre productores agropecuarios, artesanales y de reciclaje. | J33: Análisis | K33: Régimen agropecuario (Decreto 31-2024) | L33: CAPACITACIÓN | M33: https://sites.google.com/capacitacionessat.page/cultura-tributariad/cursos-virtuales-sat/impuesto-al-valor-agregado-iva/inscripci%C3%B3n-y-actualizaci%C3%B3n-de-productores | N33: Servicio/tema general para contribuyentes
... A42: Pequeños Contribuyentes | B42: Pecuario | D42: Regímenes tributarios | E42: Régimen Agropecuario | F42: Principales obligaciones tributarias del Régimen especial de Contribuyente Agropecuario (Convencional y Electrónico) | G42: Curso: obligaciones del Régimen Especial Agropecuario | H42: Capacitación virtual de la SAT sobre obligaciones del Régimen Especial Agropecuario. | J42: Análisis | K42: Régimen agropecuario (Decreto 31-2024) | L42: CAPACITACIÓN | M42: https://sites.google.com/capacitacionessat.page/cultura-tributariad/cursos-virtuales-sat/impuesto-al-valor-agregado-iva/principales-obligaciones-tributarias-del-r%C3%A9gimen-especial-de-contribuyente | N42: Servicio/tema general para contribuyentes
A43: Contribuyente General | B43: Todos los grupos | D43: Facturación electrónica y documentos tributarios | E43: Constancias de exención (CIVA y CAIS) | F43: Emisión Constancias de Adquisición de Insumos y Servicios -CAIS- | G43: Emitir constancias CAIS | H43: Requisitos, pasos y documentos para emitir constancias CAIS. | I43: Contribuyente General | J43: Grupos y categorías | K43: Marcada «SI» en el archivo Grupos y categorías | L43: SERVICIOS TRIBUTARIOS | M43: https://portal.sat.gob.gt/portal/emision-constancias-de-adquisicion-de-insumos-y-servicios-cais/ | N43: Servicio/tema general para contribuyentes
A44: Contribuyente General | B44: Todos los grupos | D44: Facturación electrónica y documentos tributarios | E44: Constancias de exención (CIVA y CAIS) | F44: Emisión Constancias de Exención de IVA -CIVA- | G44: Emitir constancias de exención de IVA (CIVA) | H44: Requisitos, pasos y documentos para emitir constancias de exención de IVA (CIVA). | I44: Contribuyente General | J44: Grupos y categorías | K44: Marcada «SI» en el archivo Grupos y categorías | L44: SERVICIOS TRIBUTARIOS | M44: https://portal.sat.gob.gt/portal/emision-constancias-de-exencion-de-iva-civa/ | N44: Servicio/tema general para contribuyentes
A45: Contribuyente General | B45: Todos los grupos | D45: Otros servicios al contribuyente | E45: Constancias y gestiones del RTU | F45: Requisitos de persona/empresa | G45: Requisitos para Abogados y Notarios | H45: Requisitos, listado de pasos, y casos especiales; para la inscripción/actualización, activación, confirmación de huella y Venta de Especies Fiscales para Abogados y Notarios. | I45: Contribuyente General | J45: Grupos y categorías | K45: Marcada «SI» en el archivo Grupos y categorías | L45: SERVICIOS TRIBUTARIOS | M45: https://portal.sat.gob.gt/portal/requisitos-de-personas-empresas/ | N45: Servicio/tema general para contribuyentes
A46: Contribuyente General | B46: Contribuyente General | D46: Consultas y verificadores | E46: Autorización y consulta | F46: Autorización de Máquinas en Agencia Virtual | G46: Autorizar máquinas registradoras en Agencia Virtual | H46: Requisitos, pasos y documentos para autorizar máquinas registradoras en Agencia Virtual. | J46: Análisis | K46: Máquinas registradoras | L46: SERVICIOS TRIBUTARIOS | M46: https://portal.sat.gob.gt/portal/requisitos-tramites-agencias/autorizacion-de-maquinas-en-agencia-virtual/ | N46: Servicio/tema general para contribuyentes
A47: Contribuyente General | B47: Contribuyente General | D47: Consultas y verificadores | E47: Autorización y consulta | F47: Consulta Autorización de Máquina | G47: Consultar si una máquina registradora está autorizada | H47: Servicio en línea para consultar si una máquina registradora está autorizada. | J47: Análisis | K47: Máquinas registradoras | L47: SERVICIOS TRIBUTARIOS | M47: https://portal.sat.gob.gt/portal/consulta-autorizacion-de-maquina/ | N47: Servicio/tema general para contribuyentes
A48: Contribuyente General | B48: Contribuyente General | D48: Cultura tributaria y capacitación | E48: Cursos por impuesto | F48: Regímenes para las Rentas de Actividades Lucrativas | G48: Curso: regímenes del ISR para negocios | H48: Capacitación virtual de la SAT sobre regímenes del ISR para negocios. | J48: Análisis | K48: Régimen General del IVA e ISR de actividades lucrativas | L48: CAPACITACIÓN | M48: https://sites.google.com/capacitacionessat.page/cultura-tributariad/cursos-virtuales-sat/impuesto-sobre-la-renta/reg%C3%ADmenes-para-las-rentas-de-actividades-lucrativas | N48: Servicio/tema general para contribuyentes
A49: Contribuyente General | B49: Contribuyente General | D49: Devoluciones y créditos fiscales | E49: ISR (Impuesto Sobre la Renta) | F49: Formulario Electrónico SAT-2350 (versión vigente) Solicitud de Devolución de Pagos en Exceso del ISR Anual | G49: Devolución de ISR anual pagado de más | H49: Información sobre: Devolución de ISR anual pagado de más. | J49: Análisis | K49: Devoluciones de ISR/IVA/ISO de actividades lucrativas | L49: SERVICIOS TRIBUTARIOS | M49: https://portal.sat.gob.gt/portal/requisitos-tramites-agencias/formulario-electronico-sat-2350-version-vigente-solicitud-de-pagos-en-exceso/ | N49: Servicio/tema general para contribuyentes
...

Sheet Operadores de comercio exterior
A1: Operadores de comercio exterior
A2: Importadores, exportadores y auxiliares de la función pública aduanera que intervienen en operaciones de comercio exterior. Orden: Categoría › Grupo › Tema › Página. «Todos los grupos» = la usan todos los grupos de la categoría. «Trámites comunes» = la usan varias categorías.
A4: Categoría | B4: Grupo | C4: Tema | D4: Subtema | E4: Página / Trámite (nombre actual) | F4: Nombre de trámite sugerido | G4: Descripción de la página | H4: Usado por (según Grupos y categorías) | I4: Origen de la clasificación | J4: Motivo / referencia | K4: Sección actual del menú | L4: URL | M4: Nota / Revisar
A5: Importadores y Exportadores | B5: Todos los grupos | C5: Exportación | D5: Declaraciones y sanciones | E5: Importación y Exportación Menor con Declaración de Oficio | F5: Importación y exportación menor con declaración de oficio | G5: Información sobre: Importación y exportación menor con declaración de oficio. | I5: Análisis | J5: Aplica a importación y exportación | K5: ADUANAS | L5: https://portal.sat.gob.gt/portal/requisitos-tramites-aduanas/importacion-y-exportacion-menor-con-declaracion-de-oficio/ | M5: Bajo menú Aduanas
A6: Importadores y Exportadores | B6: Todos los grupos | C6: Exportación | D6: Declaraciones y sanciones | E6: Sanciones Aplicables a la Importación, Exportación o Tránsito | F6: Sanciones en importación, exportación o tránsito | G6: Información sobre: Sanciones en importación, exportación o tránsito. | I6: Análisis | J6: Aplica a importación y exportación | K6: ADUANAS | L6: https://portal.sat.gob.gt/portal/sanciones-aplicables-a-la-importacion-exportacion-o-transito/ | M6: Bajo menú Aduanas
A7: Importadores y Exportadores | B7: Todos los grupos | C7: Gestiones y consultas aduaneras | D7: Aranceles y permisos | E7: Catálogo de Permisos No arancelarios. | F7: Catálogo de permisos no arancelarios | G7: Información sobre: Catálogo de permisos no arancelarios. | I7: Análisis | J7: Declaración y clasificación de mercancías | K7: ADUANAS | L7: https://portal.sat.gob.gt/portal/catalogo-de-permisos-no-arancelarios/ | M7: Bajo menú Aduanas
A8: Importadores y Exportadores | B8: Todos los grupos | C8: Gestiones y consultas aduaneras | D8: Aranceles y permisos | E8: Arancel Integrado | F8: Consultar el arancel integrado | G8: Servicio en línea para consultar el arancel integrado. | I8: Análisis | J8: Declaración y clasificación de mercancías | K8: ADUANAS | L8: https://portal.sat.gob.gt/portal/arancel-integrado/ | M8: Bajo menú Aduanas
A9: Importadores y Exportadores | B9: Todos los grupos | C9: Gestiones y consultas aduaneras | D9: Aranceles y permisos | E9: Criterio de Clasificación Arancelaria No. 01-2002, Partida Arancelaria 4011 | F9: Criterio de clasificación arancelaria 01-2002 | G9: Información sobre: Criterio de clasificación arancelaria 01-2002. | I9: Análisis | J9: Declaración y clasificación de mercancías | K9: ADUANAS | L9: https://portal.sat.gob.gt/portal/valoracion-clasificacion-y-origen-de-la-mercancia/criterio-de-clasificacion-arancelaria-no-01-2002-partida-arancelaria-4011/ | M9: Bajo menú Aduanas
A10: Importadores y Exportadores | B10: Todos los grupos | C10: Gestiones y consultas aduaneras | D10: Aranceles y permisos | E10: Notas explicativas del SAC | F10: Notas explicativas del SAC | G10: Información sobre: Notas explicativas del SAC. | I10: Análisis | J10: Declaración y clasificación de mercancías | K10: ADUANAS | L10: https://portal.sat.gob.gt/portal/aduanas/notas-explicativas-del-sistema-armonizado/ | M10: Bajo menú Aduanas
A11: Importadores y Exportadores | B11: Todos los grupos | C11: Gestiones y consultas aduaneras | D11: Aranceles y permisos | E11: Sistema Arancelario Centroamericano (SAC) | F11: Sistema Arancelario Centroamericano (SAC) | G11: Información sobre: Sistema Arancelario Centroamericano (SAC). | I11: Análisis | J11: Declaración y clasificación de mercancías | K11: ADUANAS | L11: https://portal.sat.gob.gt/portal/valoracion-clasificacion-y-origen-de-la-mercancia/sistema-arancelario-centroamericano-sac/ | M11: Bajo menú Aduanas
A12: Importadores y Exportadores | B12: Todos los grupos | C12: Gestiones y consultas aduaneras | D12: Consultas de declaraciones | E12: Consultas de FAUCAS/DUCA F | F12: Consultar FAUCA / DUCA-F | G12: Servicio en línea para consultar FAUCA / DUCA-F. | I12: Análisis | J12: Declaración y clasificación de mercancías | K12: ADUANAS | L12: https://portal.sat.gob.gt/portal/consultas-de-faucas-duca-f/ | M12: Bajo menú Aduanas
A13: Importadores y Exportadores | B13: Todos los grupos | C13: Gestiones y consultas aduaneras | D13: Consultas de declaraciones | E13: Consulta de manifiestos/ Documentos de transporte pantalla externa/ Unión Aduanera Guatemala-Honduras | F13: Consultar manifiestos de la Unión Aduanera | G13: Servicio en línea para consultar manifiestos de la Unión Aduanera. | I13: Análisis | J13: Declaración y clasificación de mercancías | K13: ADUANAS | L13: https://portal.sat.gob.gt/portal/consulta-de-manifiestos-documentos-de-transporte-pantalla-externa-union-aduanera-guatemala-honduras/ | M13: Bajo menú Aduanas
A14: Importadores y Exportadores | B14: Todos los grupos | C14: Gestiones y consultas aduaneras | D14: Consultas de declaraciones | E14: Consulta Pública Retención/Liberación | F14: Consultar mercancías retenidas o liberadas | G14: Servicio en línea para consultar mercancías retenidas o liberadas. | I14: Análisis | J14: Declaración y clasificación de mercancías | K14: ADUANAS | L14: https://portal.sat.gob.gt/portal/consulta-publica-retencion-liberacion/ | M14: Bajo menú Aduanas
A15: Importadores y Exportadores | B15: Todos los grupos | C15: Gestiones y consultas aduaneras | D15: Consultas de declaraciones | E15: Consultas Pago DUCA-F país Destino | F15: Consultar pago de DUCA-F en país de destino | G15: Servicio en línea para consultar pago de DUCA-F en país de destino. | I15: Análisis | J15: Declaración y clasificación de mercancías | K15: ADUANAS | L15: https://portal.sat.gob.gt/portal/consultas-pago-duca-f-pais-destino/ | M15: Bajo menú Aduanas
A16: Importadores y Exportadores | B16: Todos los grupos | C16: Gestiones y consultas aduaneras | D16: Consultas de declaraciones | E16: Consultas Declaración de Mercancías | F16: Consultar una declaración de mercancías | G16: Servicio en línea para consultar una declaración de mercancías. | I16: Análisis | J16: Declaración y clasificación de mercancías | K16: ADUANAS | L16: https://portal.sat.gob.gt/portal/consulta-declaracion-unica-aduanera/ | M16: Bajo menú Aduanas
... A22: Importadores y Exportadores | B22: Todos los grupos | C22: Gestiones y consultas aduaneras | D22: Declaraciones (DUA / DUCA) | E22: Presentación de la Declaración de Mercancías (DUA/FAUCA/DUT) para el proceso de análisis de riesgo | F22: Presentar la declaración para análisis de riesgo | G22: Requisitos, pasos y documentos para presentar la declaración para análisis de riesgo. | I22: Análisis | J22: Declaración y clasificación de mercancías | K22: ADUANAS | L22: https://portal.sat.gob.gt/portal/requisitos-tramites-aduanas/presentacion-de-la-declaracion-de-mercancias-dua-fauca-dut-para-el-proceso-de-analisis-de-riesgo/ | M22: Bajo menú Aduanas
A23: Importadores y Exportadores | B23: Todos los grupos | C23: Gestiones y consultas aduaneras | D23: Declaraciones (DUA / DUCA) | E23: Declaración de mercancías | F23: Programa de Modernización Integral Aduanera | G23: Información sobre el proceso de solicitud, colocación y funcionamiento del marchamo electrónico, inventario de áreas de activación y desactivación y entidades prestadoras del servicio autorizadas. | H23: Importadores y Exportadores | I23: Grupos y categorías | J23: Marcada «SI» en el archivo Grupos y categorías | K23: ADUANAS | L23: https://portal.sat.gob.gt/portal/procedimientos-aduanas/#1555105635499-a4507e58-10e9 | M23: Bajo menú Aduanas
A24: Importadores y Exportadores | B24: Todos los grupos | C24: Gestiones y consultas aduaneras | D24: Requisitos, recursos y sistemas | E24: Recursos Aduaneros | F24: Recursos aduaneros (impugnaciones) | G24: Información sobre: Recursos aduaneros (impugnaciones). | I24: Análisis | J24: Recursos y mercancías en abandono | K24: ADUANAS | L24: https://portal.sat.gob.gt/portal/recursos-aduaneros/ | M24: Bajo menú Aduanas
A25: Importadores y Exportadores | B25: Todos los grupos | C25: Gestiones y consultas aduaneras | D25: Requisitos, recursos y sistemas | E25: Rescate de Mercancías Caídas en Abandono | F25: Rescatar mercancías en abandono | G25: Requisitos, pasos y documentos para rescatar mercancías en abandono. | I25: Análisis | J25: Recursos y mercancías en abandono | K25: ADUANAS | L25: https://portal.sat.gob.gt/portal/requisitos-tramites-aduanas/rescate-de-mercancias-caidas-en-abandono/ | M25: Bajo menú Aduanas
A26: Importadores y Exportadores | B26: Todos los grupos | C26: Inscripción y actualización en el RTU | D26: Actualizar tus datos | E26: Actualización de Datos, por medio de Agencia Virtual | F26: Actualizar tus datos en Agencia Virtual | G26: Requisitos, pasos y documentos para actualizar tus datos en Agencia Virtual. | H26: Importadores y Exportadores | I26: Grupos y categorías | J26: Marcada «SI» en el archivo Grupos y categorías | K26: SERVICIOS TRIBUTARIOS | L26: https://farm3.sat.gob.gt/menu/login.jsf | M26: Servicio/tema general para contribuyentes
A27: Importadores y Exportadores | B27: Importadores | C27: Capacitación y orientación aduanera | D27: Cursos | E27: Sistema de Franquicias Electrónicas | F27: Curso: sistema de franquicias electrónicas | G27: Capacitación virtual de la SAT sobre sistema de franquicias electrónicas. | I27: Análisis | J27: Franquicias | K27: CAPACITACIÓN | L27: https://sites.google.com/capacitacionessat.page/eventosenvivo/p%C3%A1gina-principal/sistema-de-franquicias-electr%C3%B3nicas | M27: Coincide con palabra clave de comercio exterior/aduanas
A28: Importadores y Exportadores | B28: Importadores | C28: Gestiones y consultas aduaneras | D28: Declaraciones (DUA / DUCA) | E28: Declaración de mercancías | F28: Sistema de Franquicias Electrónicas | G28: Información sobre documentación técnica de orientación al usuario externo para solicitudes de Franquicia Electrónica y videos informativos. | H28: Importadores y Exportadores: Importadores, OEA | I28: Grupos y categorías | J28: Marcada «SI» en el archivo Grupos y categorías | K28: ADUANAS | L28: https://portal.sat.gob.gt/portal/procedimientos-aduanas/#1555105635499-a4507e58-10e9 | M28: Bajo menú Aduanas
A29: Importadores y Exportadores | B29: Importadores | C29: Gestiones y consultas aduaneras | D29: Requisitos, recursos y sistemas | E29: Requisitos Gestiones en Aduanas | F29: Requisitos sobre documentos para Importación y Admisión Temporal | G29: Información y requisitos sobre recepción de seguro de caución de importacion y admisión temporal, presentación de mercancia de importación y admisiones temporales para cargos y fianzas y requisitos para la importación temporal de vehículos de turismo. | H29: Importadores y Exportadores: Importadores, OEA | I29: Grupos y categorías | J29: Marcada «SI» en el archivo Grupos y categorías | K29: ADUANAS | L29: https://portal.sat.gob.gt/portal/requisitos-de-aduanas/ | M29: Bajo menú Aduanas
A30: Importadores y Exportadores | B30: Importadores | C30: Importación | D30: Compras en el extranjero | E30: Pasos Previos a tu Importacion de Mercacias Via Aerea | F30: Pasos antes de importar por vía aérea | G30: Información sobre: Pasos antes de importar por vía aérea. | I30: Análisis | J30: Importación de mercancías y vehículos | K30: ADUANAS | L30: https://portal.sat.gob.gt/portal/programa-miad/componente-procesos-2/#1623281274865-df599d08-4b3c | M30: Bajo menú Aduanas
A31: Importadores y Exportadores | B31: Importadores | C31: Importación | D31: Compras en el extranjero | E31: Consideraciones para hacer tu envio via Aerea | F31: Qué considerar al enviar por vía aérea | G31: Información general: Qué considerar al enviar por vía aérea | I31: Análisis | J31: Importación de mercancías y vehículos | K31: ADUANAS | L31: https://portal.sat.gob.gt/portal/programa-miad/componente-procesos-2/#1623281275085-8c3227fc-5354 | M31: Bajo menú Aduanas
A32: Importadores y Exportadores | B32: Importadores | C32: Importación | D32: Compras en el extranjero | E32: Consideraciones para hacer tu Compra | F32: Qué considerar antes de comprar en el extranjero | G32: Información general: Qué considerar antes de comprar en el extranjero | I32: Análisis | J32: Importación de mercancías y vehículos | K32: ADUANAS | L32: https://portal.sat.gob.gt/portal/programa-miad/componente-procesos-2/#1623281275316-efbcfcd7-9f48 | M32: Bajo menú Aduanas
A33: Importadores y Exportadores | B33: Importadores | C33: Importación | D33: Importación de vehículos | E33: Alza de importación de vehículos | F33: Alza e importación de vehículos | G33: Información sobre: Alza e importación de vehículos. | I33: Análisis | J33: Importación de mercancías y vehículos | K33: ADUANAS | L33: https://portal.sat.gob.gt/portal/alza-e-importacion-vehiculos/#1510763502627-ec3a24b4-76f4 | M33: Bajo menú Aduanas
A34: Importadores y Exportadores | B34: Importadores | C34: Importación | D34: Importación de vehículos | E34: Comprobación del valor en la importación de vehículos automotores terrestres usados | F34: Comprobar el valor de un vehículo usado importado | G34: Requisitos, pasos y documentos para comprobar el valor de un vehículo usado importado. | I34: Análisis | J34: Importación de mercancías y vehículos | K34: SERVICIOS TRIBUTARIOS | L34: https://portal.sat.gob.gt/portal/comprobacion-valor-de-importacion/ | M34: Coincide con palabra clave de comercio exterior/aduanas
A35: Importadores y Exportadores | B35: Importadores | C35: Importación | D35: Importación de vehículos | E35: Importación de Vehículos | F35: Importar un vehículo | G35: Requisitos, pasos y documentos para importar un vehículo. | I35: Análisis | J35: Importación de mercancías y vehículos | K35: ADUANAS | L35: https://portal.sat.gob.gt/portal/alza-e-importacion-vehiculos/#1510763502681-dff4b62b-fd76 | M35: Bajo menú Aduanas
A36: Importadores y Exportadores | B36: Importadores | C36: Importación | D36: Importación de vehículos | E36: Inscripción de Vehículos para Importadores de Vehículos Nuevos | F36: Inscribir vehículos nuevos (importadores) | G36: Requisitos, pasos y documentos para inscribir vehículos nuevos (importadores). | I36: Análisis | J36: Importación de mercancías y vehículos | K36: SERVICIOS TRIBUTARIOS | L36: https://portal.sat.gob.gt/portal/requisitos-tramites-agencias/inscripcion-de-vehiculos-para-importadores-de-vehiculos-nuevos/ | M36: Coincide con palabra clave de comercio exterior/aduanas
A37: Importadores y Exportadores | B37: Importadores | C37: Importación | D37: Proceso de importación | E37: Generalidades de la importación de mercancías | F37: Curso: generalidades de la importación | G37: Capacitación virtual de la SAT sobre generalidades de la importación. | I37: Análisis | J37: Importación de mercancías y vehículos | K37: CAPACITACIÓN | L37: https://sites.google.com/capacitacionessat.page/cultura-tributariad/cursos-virtuales-sat/aduanas/20-generalidades-de-la-importaci%C3%B3n-de-mercanc%C3%Adas | M37: Coincide con palabra clave de comercio exterior/aduanas
A38: Importadores y Exportadores | B38: Importadores | C38: Importación | D38: Proceso de importación | E38: Requisitos para Inscripccion en el Registro de importadores | F38: Inscribirte como importador | G38: Requisitos, pasos y documentos para inscribirte como importador. | I38: Análisis | J38: Importación de mercancías y vehículos | K38: ADUANAS | L38: https://portal.sat.gob.gt/portal/requisitos-para-inscripccion-en-el-registro-de-importadores/ | M38: Bajo menú Aduanas
A39: Importadores y Exportadores | B39: Importadores | C39: Importación | D39: Proceso de importación | E39: Presentación de Declaración de Mercancías de Importación y Admisiones Temporales para Cargos y Fianza | F39: Presentar declaración de importación con fianza | G39: Requisitos, pasos y documentos para presentar declaración de importación con fianza. | I39: Análisis | J39: Importación de mercancías y vehículos | K39: ADUANAS | L39: https://portal.sat.gob.gt/portal/requisitos-tramites-aduanas/presentacion-de-declaracion-de-mercancias-de-importacion-y-admisiones-temporales-para-cargos-y-fianza/ | M39: Bajo menú Aduanas
A40: Importadores y Exportadores | B40: Importadores | C40: Importación | D40: Proceso de importación | E40: Pólizas de Importación | F40: Pólizas de importación | G40: Información sobre: Pólizas de importación. | I40: Análisis | J40: Importación de mercancías y vehículos | K40: ADUANAS | L40: https://portal.sat.gob.gt/portal/polizas-de-importacion/ | M40: Bajo menú Aduanas
A41: Importadores y Exportadores | B41: Importadores | C41: Importación | D41: Tablas de valores de vehículos | E41: Acuerdo de Directorio Número 24-2024 que aprueba la Tabla de Valores Imponibles del Impuesto Específico a la Primera Matrícula para la Importación de Vehículos Automotores Terrestre Usados para el año 2025. | F41: Acuerdo que aprueba la tabla de IPRIMA de vehículos usados | G41: Información sobre: Acuerdo que aprueba la tabla de IPRIMA de vehículos usados. | I41: Análisis | J41: Importación de mercancías y vehículos | K41: SERVICIOS TRIBUTARIOS | L41: https://portal.sat.gob.gt/portal/descarga/1895/legislacion-aduanera/82515/acuerdo-de-directorio-numero-24-2024-que-aprueba-la-tabla-de-valores-imponibles-del-impuesto-especifico-a-la-primera-matricula-para-la-importacion-de-vehiculos-automotores-terrestre-usados-para.pdf | M41: Coincide con palabra clave de comercio exterior/aduanas
... A51: Importadores y Exportadores | B51: Importadores | C51: Vehículos (como propietario) | D51: Placas de distribuidor | E51: Asignación de Placas de Uso Distribuidor | F51: Solicitar placas de distribuidor | G51: Requisitos, pasos y documentos para solicitar placas de distribuidor. | I51: Análisis | J51: Placas de distribuidor para importadores y distribuidores de vehículos | K51: SERVICIOS TRIBUTARIOS | L51: https://portal.sat.gob.gt/portal/requisitos-tramites-agencias/asignacion-de-placas-de-uso-distribuidor/ | M51: Servicio/tema general para contribuyentes
A52: Importadores y Exportadores | B52: Importadores | C52: Agregada desde «Grupos y categorías» | F52: Importación | G52: Conceptos generales sobre importación de mercancias y buenas practicas sugeridas desde la Modernización Integral Aduanera. | H52: Importadores y Exportadores: Importadores, OEA | I52: Grupos y categorías | J52: Marcada «SI» en el archivo Grupos y categorías | L52: https://portal.sat.gob.gt/portal/programa-miad/componente-procesos/importacion/#1623281268015-fb939ea7-9dfb
A53: Importadores y Exportadores | B53: Importadores | C53: Agregada desde «Grupos y categorías» | F53: Página | G53: Pasos previos a tu importación de mercancías vía aérea Información sobre requisitos, consideraciones, documentos necesarios y procesos con los pasos previos a una importación definitiva desde el marco de la Modernización Integral Aduanera. | H53: Importadores y Exportadores: Importadores, OEA | I53: Grupos y categorías | J53: Marcada «SI» en el archivo Grupos y categorías | L53: https://portal.sat.gob.gt/portal/programa-miad/componente-procesos/importacion/#1623281274865-df599d08-4b3c
